Workbook

Sheet Wind and Seismic
A1: wind load paramets | M1: seismic base shear
A2: kzt | B2: 1 | M2: Ss | N2: 0.087 | O2: g
A3: kd | B3: 1 | M3: S1 | N3: 0.057 | O3: g
A4: I | B4: 1 | M4: SDS | N4: =2/3*1.6*N2 -> 0.0928 | O4: g
A5: V | B5: 173 | C5: mph | D5: Number of Columns | E5: 6 | M5: SD1 | N5: =2/3*2.4*N3 -> 0.0912 | O5: g
A6: exposure | B6: C | M6: Ri | N6: 3
A7: α | B7: =IF(B6="C",9.5,11.5) -> 9.5 | M7: IE | N7: 1.5
A8: Zg | B8: =IF(B6="C",900,700) -> 900 | C8: ft | M8: TL | N8: 12 | O8: sec
A9: G | B9: 1 | M9: Ti | N9: 2.0827 | O9: sec
A10: Cf | B10: 0.6 | M10: Ts | N10: =N5/N4 -> 0.98275862 | O10: sec
A11: λ | B11: 0.6 | M11: Sai | N11: =IF(N9<N10,N4,IF(N9>N8,N5*N8/N9^2,N5/N9)) -> 0.043789312
A12: λ(0.00256 Kzt Kd I V2) | B12: =B11*0.00256*B2*B3*B4*B5^2 -> 45.970944 | C12: psf | M12: λ | N12: 0.7
A13: column | D13: column | G13: column | J13: column | M13: Ai | N13: =MAX(N12*N11*N7/N6,0.36*N3*N7/N6) -> 0.015326259 | O13: ft/s2
A14: Bay Number | B14: 1 | D14: Bay Number | E14: 2 | G14: Bay Number | H14: 3 | J14: Bay Number | K14: 4 | M14: COM | N14: =(B29+E29+H29+K29+B47+E47+H47+K47+(B60*B64))/B70 -> 133.69911
A15: Thickness | B15: 0.375 | C15: in | D15: Thickness | E15: 0.375 | F15: in | G15: Thickness | H15: 0.375 | I15: in | J15: Thickness | K15: 0 | L15: in | M15: V | N15: =N13*B70 -> 69.032864 | O15: kips
A16: hi | B16: 0 | C16: ft | D16: hi | E16: =B18 -> 43.4139 | G16: hi | H16: =E18 -> 86.8278 | I16: ft | J16: hi | K16: 0 | L16: ft | M16: Seismic base moment | N16: =N15*N14 -> 9229.6323 | O16: kips-ft
A17: Height of the cylinder | B17: 43.4139 | C17: ft | D17: Height of the cylinder | E17: 43.4139 | F17: ft | G17: Height of the cylinder | H17: 47.1639 | I17: ft | J17: Height of the cylinder | K17: 0 | L17: ft
A18: hf | B18: =B16+B17 -> 43.4139 | C18: ft | D18: hf | E18: =E16+E17 -> 86.8278 | G18: hf | H18: =H16+H17 -> 133.9917 | I18: ft | J18: hf | K18: =K16+K17 -> 0 | L18: ft
A19: Diameter of the cylinder | B19: 2.5 | C19: ft | D19: Diameter of the cylinder | E19: 2.5 | F19: ft | G19: Diameter of the cylinder | H19: 2.5 | I19: ft | J19: Diameter of the cylinder | K19: 0 | L19: ft
A20: Awind | B20: =IF(B15=0,0,$E$5*B19*B17) -> 651.2085 | C20: ft2 | D20: Awind | E20: =IF(E15=0,0,$E$5*E19*E17) -> 651.2085 | F20: ft2 | G20: Awind | H20: =IF(H15=0,0,$E$5*H19*H17) -> 707.4585 | I20: ft2 | J20: Awind | K20: =IF(K15=0,0,$E$5*K19*K17) -> 0 | L20: ft2
A21: Centroid | B21: =B16+B17/2 -> 21.70695 | C21: ft | D21: Centroid | E21: =E16+E17/2 -> 65.12085 | F21: ft | G21: Centroid | H21: =H16+H17/2 -> 110.40975 | I21: ft | J21: Centroid | K21: =K16+K17/2 -> 0 | L21: ft
A22: kzi | B22: =2.01*(MAX(B16,15)/$B$8)^(2/$B$7) -> 0.84888415 | D22: kzi | E22: =2.01*(MAX(E16,15)/$B$8)^(2/$B$7) -> 1.0617303 | G22: kzi | H22: =2.01*(MAX(H16,15)/$B$8)^(2/$B$7) -> 1.228539 | J22: kzi | K22: =2.01*(MAX(K16,15)/$B$8)^(2/$B$7) -> 0.84888415
A23: kzf | B23: =2.01*(MAX(B18,15)/$B$8)^(2/$B$7) -> 1.0617303 | D23: kzf | E23: =2.01*(MAX(E18,15)/$B$8)^(2/$B$7) -> 1.228539 | G23: kzf | H23: =2.01*(MAX(H18,15)/$B$8)^(2/$B$7) -> 1.3460343 | J23: kzf | K23: =2.01*(MAX(K18,15)/$B$8)^(2/$B$7) -> 0.84888415
A24: qzi | B24: =B12*B22 -> 39.024006 | C24: psf | D24: qzi | E24: =B12*E22 -> 48.808746 | F24: psf | G24: qzi | H24: =B12*H22 -> 56.477099 | I24: psf | J24: qzi | K24: =MAX(K22*$B$12,30*$B$10) -> 39.024006 | L24: psf
A25: qzf | B25: =B12*B23 -> 48.808746 | C25: psf | D25: qzf | E25: =B12*E23 -> 56.477099 | F25: psf | G25: qzf | H25: =B12*H23 -> 61.878469 | I25: psf | J25: qzf | K25: =MAX(K23*$B$12,30*$B$10) -> 39.024006 | L25: psf
A26: F | B26: =MAX(30*B10*B20/1000,B9*B10*(B24+B25)/2*B20/1000) -> 17.15923 | C26: kips | D26: F | E26: =MAX(30*B10*E20/1000,B9*B10*(E24+E25)/2*E20/1000) -> 20.568911 | F26: kips | G26: F | H26: =MAX(30*B10*H20/1000,B9*B10*(H24+H25)/2*H20/1000) -> 25.119496 | I26: kips | J26: F | K26: =(K24+K25)/2*K20/1000 -> 0 | L26: kips | M26: Wind base shear | N26: =K26+H26+E26+B26 -> 62.847637 | O26: kips
A27: F location | B27: =B16+((B24*B17^2/2+2/3*0.5*B17^2*(B25-B24))/(B24*B17+0.5*B17*(B25-B24))) -> 22.513016 | C27: ft | D27: F location | E27: =E16+((E24*E17^2/2+2/3*0.5*E17^2*(E25-E24))/(E24*E17+0.5*E17*(E25-E24))) -> 65.647849 | F27: ft | G27: F location | H27: =H16+((H24*H17^2/2+2/3*0.5*H17^2*(H25-H24))/(H24*H17+0.5*H17*(H25-H24))) -> 110.76848 | I27: ft | J27: F location | K27: 0 | L27: ft
A28: Wind moment At base | B28: =B27*B26 -> 386.30602 | C28: kips | D28: Wind moment At base | E28: =E27*E26 -> 1350.3048 | F28: kips | G28: Wind moment At base | H28: =H27*H26 -> 2782.4485 | I28: kips | J28: Wind moment At base | K28: 0 | L28: kips | M28: Wind base moment | N28: =K28+H28+E28+B28 -> 4519.0593 | O28: kips-ft
A29: Center of mass x weight | B29: =B30*B21 -> 814.12383 | D29: Center of mass x weight | E29: =E30*E21 -> 2629.5939 | G29: Center of mass x weight | H29: =H30*H21 -> 4753.3973 | J29: Center of mass x weight | K29: =K30*K21 -> 0
A30: Weight | B30: =(PI()/4*(B19^2-(B19-2*B15/12)^2)*B17*490/1000*E5)+($H$54/3) -> 37.505215 | C30: kips | D30: Weight | E30: =(PI()/4*(E19^2-(E19-2*E15/12)^2)*E17*490/1000*E5)+($H$52/2+$H$54/3) -> 40.380215 | F30: kips | G30: Weight | H30: =(PI()/4*(H19^2-(H19-2*H15/12)^2)*H17*490/1000*E5)+($H$52/2+$H$54/3) -> 43.052333 | I30: kips | J30: Weight | K30: =PI()/4*(K19^2-(K19-2*K15/12)^2)*K17*490/1000*E5 -> 0 | L30: kips | M30: weight of steel | N30: =K30+H30+E30+B30 -> 120.93776 | O30: kips
A31: riser | D31: riser | G31: riser | J31: riser
A32: Bay Number | B32: 1 | D32: Bay Number | E32: 2 | G32: Bay Number | H32: 3 | J32: Bay Number | K32: 4
A33: Thickness | B33: 0.625 | C33: in | D33: Thickness | E33: 0.625 | F33: in | G33: Thickness | H33: 0.625 | I33: in | J33: Thickness | K33: 0 | L33: in
A34: hi | B34: 0 | C34: ft | D34: hi | E34: =B36 -> 43.4139 | G34: hi | H34: =E36 -> 86.8278 | I34: ft | J34: hi | K34: 0 | L34: ft
A35: Height of the riser | B35: 43.4139 | C35: ft | D35: Height of the riser | E35: 43.4139 | F35: ft | G35: Height of the riser | H35: 29.2552 | I35: ft | J35: Height of the riser | K35: 0 | L35: ft
A36: hf | B36: =B34+B35 -> 43.4139 | C36: ft | D36: hf | E36: =E34+E35 -> 86.8278 | G36: hf | H36: =H34+H35 -> 116.083 | I36: ft | J36: hf | K36: =K34+K35 -> 0 | L36: ft
A37: Diameter of the riser | B37: 4 | C37: ft | D37: Diameter of the riser | E37: 4 | F37: ft | G37: Diameter of the riser | H37: 4 | I37: ft | J37: Diameter of the riser | K37: 0 | L37: ft
A38: Awind | B38: =IF(B33=0,0,B37*B35) -> 173.6556 | C38: ft2 | D38: Awind | E38: =IF(E33=0,0,E37*E35) -> 173.6556 | F38: ft2 | G38: Awind | H38: =IF(H33=0,0,H37*H35) -> 117.0208 | I38: ft2 | J38: Awind | K38: =IF(K33=0,0,K37*K35) -> 0 | L38: ft2
A39: Centroid | B39: =B34+B35/2 -> 21.70695 | C39: ft | D39: Centroid | E39: =E34+E35/2 -> 65.12085 | F39: ft | G39: Centroid | H39: =H34+H35/2 -> 101.4554 | I39: ft | J39: Centroid | K39: =K34+K35/2 -> 0 | L39: ft
A40: kzi | B40: =2.01*(MAX(B34,15)/$B$8)^(2/$B$7) -> 0.84888415 | D40: kzi | E40: =2.01*(MAX(E34,15)/$B$8)^(2/$B$7) -> 1.0617303 | G40: kzi | H40: =2.01*(MAX(H34,15)/$B$8)^(2/$B$7) -> 1.228539 | J40: kzi | K40: =2.01*(MAX(K34,15)/$B$8)^(2/$B$7) -> 0.84888415
...

Sheet Loads
A1: Snow Load | E1: Roof Live Load | I1: Live Load | M1: Load Combination | Q1: P | S1: M
A2: Diameter of tank | B2: 56 | C2: ft | E2: Min Roof Live Load | F2: 15 | G2: psf | I2: Live Load | J2: 0 | K2: kips | M2: D | Q2: ='Wind and Seismic'!B70 -> 4504.2213 | S2: 0
A3: Height to consider | B3: 9.52 | E3: Area to consider | F3: =B4 -> 1674.8459 | G3: ft2 | M3: D + L | Q3: ='Wind and Seismic'!B70+J2 -> 4504.2213 | S3: 0
A4: Area to consider | B4: =PI()*B2*B3 -> 1674.8459 | C4: ft2 | E4: Roof Live Load | F4: =F2*F3/1000 -> 25.122688 | G4: kips | M4: D + (Lr or S) | Q4: ='Wind and Seismic'!B70+(MAX(B11,F4)) -> 4542.2068 | S4: 0
A5: Ground snow load | B5: 25 | C5: psf | M5: D + 0.75L + 0.75(Lr or S) | Q5: ='Wind and Seismic'!B70+0.75*J2+0.75*(MAX(B11,F4)) -> 4532.7105 | S5: 0
A6: Exposure Factor | B6: C | M6: D + 0.6(W or E) | Q6: ='Wind and Seismic'!B70 -> 4504.2213 | S6: =0.6*(MAX('Wind and Seismic'!B74,'Wind and Seismic'!N16)) -> 8192.0393
A7: Ce | B7: =IF(B6="C",0.9,0.8) -> 0.9 | M7: D + 0.75L + 0.75(0.6W or 0.6E) + 0.75(Lr or S) | Q7: ='Wind and Seismic'!B70+(0.75*J2)+(0.75*(MAX(B11,F4))) -> 4532.7105 | S7: =0.45*(MAX('Wind and Seismic'!B74,'Wind and Seismic'!N16)) -> 6144.0295
A8: Ct | B8: 1.2 | M8: 0.6D + 0.6(W or E) | Q8: =0.6*'Wind and Seismic'!B70 -> 2702.5328 | S8: =0.6*(MAX('Wind and Seismic'!B74,'Wind and Seismic'!N16)) -> 8192.0393
A9: Importance Factor | B9: RC IV
A10: Is | B10: =IF(B9="RC II",1,IF(B9="RC III",1.1,1.2)) -> 1.2
A11: Snow load | B11: =0.7*B4*B5*B7*B8*B10/1000 -> 37.985504 | C11: kips
A14: 0.6D + 0.6(W or E) | E14: D + 0.75L + 0.75(0.6W or 0.6E) + 0.75(Lr or S) | I14: D + 0.6(W or E)
A15: =Q8 -> 2702.5328 | B15: kips | E15: =Q7 -> 4532.7105 | F15: kips | I15: =Q6 -> 4504.2213 | K15: kips
A16: =S8 -> 8192.0393 | B16: ft-kips | E16: =S7 -> 6144.0295 | F16: ft-kips | I16: =S6 -> 8192.0393 | K16: ft-kips
A17: fa | B17: fb | C17: check | E17: fa | F17: fb | G17: check | I17: fa | K17: fb | L17: check
A18: {=Q8/'Design Table'!$D$4:$D$12} -> #DIV/0! | B18: {=S8*12/'Design Table'!$F$4:$F$12} -> #DIV/0! | C18: {=(A18:A26/'Design Table'!$M$22:$M$30)+(B18:B26/'Design Table'!$N$22:$N$30)} -> #DIV/0! | E18: {=Q7/'Design Table'!$D$4:$D$12} -> #DIV/0! | F18: {=S7*12/'Design Table'!$F$4:$F$12} -> #DIV/0! | G18: {=(E18:E26/'Design Table'!$M$22:$M$30)+(F18:F26/'Design Table'!$N$22:$N$30)} -> #DIV/0! | I18: {=Q6/'Design Table'!$D$4:$D$12} -> #DIV/0! | K18: {=S6*12/'Design Table'!$F$4:$F$12} -> #DIV/0! | L18: {=(I18:I26/'Design Table'!$M$22:$M$30)+(K18:K26/'Design Table'!$N$22:$N$30)} -> #DIV/0!
A19: 77.433961 | B19: 385.06028 | C19: 26.128941 | E19: 129.87288 | F19: 288.79521 | G19: 23.988617 | I19: 129.0566 | K19: 385.06028 | L19: 29.286744
A20: 77.433961 | B20: 385.06028 | C20: 26.056946 | E20: 129.87288 | F20: 288.79521 | G20: 23.867866 | I20: 129.0566 | K20: 385.06028 | L20: 29.166751
A21: 77.433961 | B21: 385.06028 | C21: 26.056946 | E21: 129.87288 | F21: 288.79521 | G21: 23.867866 | I21: 129.0566 | K21: 385.06028 | L21: 29.166751
A22: #DIV/0! | B22: #DIV/0! | C22: #DIV/0! | E22: #DIV/0! | F22: #DIV/0! | G22: #DIV/0! | I22: #DIV/0! | K22: #DIV/0! | L22: #DIV/0!
A23: #DIV/0! | B23: #DIV/0! | C23: #DIV/0! | E23: #DIV/0! | F23: #DIV/0! | G23: #DIV/0! | I23: #DIV/0! | K23: #DIV/0! | L23: #DIV/0!
A24: 29.053059 | B24: 90.390203 | C24: 6.6357368 | E24: 48.728031 | F24: 67.792652 | G24: 6.4733713 | I24: 48.421764 | K24: 90.390203 | L24: 7.711776
A25: 29.053059 | B25: 90.390203 | C25: 6.6863675 | E25: 48.728031 | F25: 67.792652 | G25: 6.5582896 | I25: 48.421764 | K25: 90.390203 | L25: 7.7961605
A26: 29.053059 | B26: 90.390203 | C26: 6.6863675 | E26: 48.728031 | F26: 67.792652 | G26: 6.5582896 | I26: 48.421764 | K26: 90.390203 | L26: 7.7961605

Sheet Design Table
G1: Gravity Loads(per segemnet) | J1: Gravity Loads(cumulative) | M1: Wind Load (per segement) | T1: Seismic Load (per segment)
A2: Segement | B2: Diameter(in) | C2: Thickness(in) | D2: A (in2) | E2: I (in4) | F2: S (in3) | G2: Wwater | H2: Wsnow | I2: Wself-weight | J2: Wwater | K2: Wsnow | L2: Wself-weight | M2: Fwind | N2: V wind | O2: Base Elevation | P2: Load Location | Q2: Arm Length | R2: F x Arm | S2: Mwind | T2: Fseismic | U2: Weight | V2: Centroid | W2: Base Elevation | X2: Mseismic
A3: Tank | B3: 0 | C3: 0 | D3: - | E3: - | F3: - | G3: ='Wind and Seismic'!B68 -> 4199 | H3: 0 | I3: ='Wind and Seismic'!B63 -> 133.145 | J3: {=G3:I3} -> 4199 | K3: 0 | L3: 133.145 | M3: =0.6*('Wind and Seismic'!B59) -> 36.255257 | N3: =M3 -> 36.255257 | O3: ='Wind and Seismic'!B53 -> 121.6253 | P3: ='Wind and Seismic'!B60 -> 136.6253 | Q3: =P3-O3 -> 15 | R3: =M3*(Q3) -> 543.82885 | S3: =R3 -> 543.82885 | T3: =0.6*('Wind and Seismic'!$N$15) -> 41.419718 | U3: ='Wind and Seismic'!B64 -> 4332.145 | V3: ='Wind and Seismic'!B60 -> 136.6253 | W3: {=O3:O12} -> 121.6253
A4: C4 | B4: =('Wind and Seismic'!K19)*12 -> 0 | C4: ='Wind and Seismic'!K15 -> 0 | D4: =PI()/4*(B4^2-(B4-C4*2)^2) -> 0 | E4: =PI()/64*(B4^4-(B4-C4*2)^4) -> 0 | F4: =IF(B4=0,0,E4/(B4/2)) -> 0 | G4: 0 | H4: =IF(C4=0,0,(D4/(('Wind and Seismic'!E5*D7)+D12)*H3)) -> 0 | I4: ='Wind and Seismic'!K30/'Wind and Seismic'!$E$5 -> 0 | J4: =IF(C4=0,0,((D4/('Wind and Seismic'!$E$5*$D$7+$D$12))*J3)+G3) -> 0 | K4: =(K3+H4)/'Wind and Seismic'!$E$5 -> 0 | L4: =(L3/'Wind and Seismic'!$E$5)+I4 -> 22.190833 | M4: =0.6*('Wind and Seismic'!K26/'Wind and Seismic'!$E$5) -> 0 | N4: =N3*(D7/(('Wind and Seismic'!$E$5*D7)+D12))+M4 -> 4.1839778 | O4: ='Wind and Seismic'!K16 -> 0 | P4: ='Wind and Seismic'!K27 -> 0 | Q4: =P4-O4 -> 0 | R4: =M4*(Q4) -> 0 | S4: =IF(M4=0,0,R4+M3*(P3-O4)) -> 0 | T4: =0.6*('Wind and Seismic'!$N$15) -> 41.419718 | U4: ='Wind and Seismic'!K30/'Wind and Seismic'!$E$5 -> 0 | V4: ='Wind and Seismic'!K21 -> 0 | W4: 0
A5: C3 | B5: =('Wind and Seismic'!H19)*12 -> 30 | C5: ='Wind and Seismic'!H15 -> 0.375 | D5: =PI()/4*(B5^2-(B5-C5*2)^2) -> 34.901131 | E5: =PI()/64*(B5^4-(B5-C5*2)^4) -> 3829.4448 | F5: =IF(B5=0,0,E5/(B5/2)) -> 255.29632 | G5: =G4 -> 0 | H5: =IF(C5=0,0,(D5/(('Wind and Seismic'!E5*D7)+D12)*H3)) -> 0 | I5: ='Wind and Seismic'!H30/'Wind and Seismic'!$E$5 -> 7.1753888 | J5: =IF(C5=0,0,((D5/('Wind and Seismic'!$E$5*$D$7+$D$12))*J3)+G4) -> 484.57864 | K5: =K4+H5 -> 0 | L5: =L4+I5 -> 29.366222 | M5: =0.6*('Wind and Seismic'!H26/'Wind and Seismic'!$E$5) -> 2.5119496 | N5: =N4+M5 -> 6.6959274 | O5: ='Wind and Seismic'!H16 -> 86.8278 | P5: ='Wind and Seismic'!H27 -> 110.76848 | Q5: =P5-O5 -> 23.940685 | R5: =M5*(Q5) -> 60.137794 | S5: =R5+(M3*(D7/(('Wind and Seismic'!$E$5*D7)+D12)))*(P3-O5)+M4*(P4-O5) -> 268.48943 | T5: =0.6*('Wind and Seismic'!$N$15) -> 41.419718 | U5: ='Wind and Seismic'!H30/'Wind and Seismic'!$E$5 -> 7.1753888 | V5: ='Wind and Seismic'!H21 -> 110.40975 | W5: 86.8278 | X5: =0.6*('Wind and Seismic'!$N$13*(U3*(D5/('Wind and Seismic'!$E$5*$D$7+$D$12))*(V3-W5)+U4*(V4-W5)+U5*(V5-W5))) -> 230.49319
A6: C2 | B6: =('Wind and Seismic'!E19)*12 -> 30 | C6: ='Wind and Seismic'!E15 -> 0.375 | D6: =PI()/4*(B6^2-(B6-C6*2)^2) -> 34.901131 | E6: =PI()/64*(B6^4-(B6-C6*2)^4) -> 3829.4448 | F6: =IF(B6=0,0,E6/(B6/2)) -> 255.29632 | G6: =G5 -> 0 | H6: =IF(C6=0,0,(D6/(('Wind and Seismic'!E5*D7)+D12)*H3)) -> 0 | I6: ='Wind and Seismic'!E30/'Wind and Seismic'!$E$5 -> 6.7300358 | J6: =J5+G6 -> 484.57864 | K6: =K5+H6 -> 0 | L6: =L5+I6 -> 36.096258 | M6: =0.6*('Wind and Seismic'!E26/'Wind and Seismic'!$E$5) -> 2.0568911 | N6: =N5+M6 -> 8.7528185 | O6: ='Wind and Seismic'!E16 -> 43.4139 | P6: ='Wind and Seismic'!E27 -> 65.647849 | Q6: =P6-O6 -> 22.233949 | R6: =M6*(Q6) -> 45.732812 | S6: =R6+(M3*(D7/(('Wind and Seismic'!$E$5*D7)+D12)))*(P3-O6)+M4*(P4-O6)+M5*(P5-O6) -> 604.91857 | T6: =0.6*('Wind and Seismic'!$N$15) -> 41.419718 | U6: ='Wind and Seismic'!E30/'Wind and Seismic'!$E$5 -> 6.7300358 | V6: ='Wind and Seismic'!E21 -> 65.12085 | W6: 43.4139 | X6: =0.6*('Wind and Seismic'!$N$13*(U3*(D6/('Wind and Seismic'!$E$5*$D$7+$D$12))*(V3-W6)+U4*(V4-W6)+U5*(V5-W6)+U6*(V6-W6))) -> 434.29063
A7: C1 | B7: =('Wind and Seismic'!B19)*12 -> 30 | C7: ='Wind and Seismic'!B15 -> 0.375 | D7: =PI()/4*(B7^2-(B7-C7*2)^2) -> 34.901131 | E7: =PI()/64*(B7^4-(B7-C7*2)^4) -> 3829.4448 | F7: =IF(B7=0,0,E7/(B7/2)) -> 255.29632 | G7: =G6 -> 0 | H7: =IF(C7=0,0,(D7/(('Wind and Seismic'!E5*D7)+D12)*H3)) -> 0 | I7: ='Wind and Seismic'!B30/'Wind and Seismic'!$E$5 -> 6.2508692 | J7: =J6+G7 -> 484.57864 | K7: =K6+H7 -> 0 | L7: =L6+I7 -> 42.347127 | M7: =0.6*('Wind and Seismic'!B26/'Wind and Seismic'!$E$5) -> 1.715923 | N7: =N6+M7 -> 10.468742 | O7: ='Wind and Seismic'!B16 -> 0 | P7: ='Wind and Seismic'!B27 -> 22.513016 | Q7: =P7-O7 -> 22.513016 | R7: =M7*(Q7) -> 38.630602 | S7: =R7+(M3*(D7/(('Wind and Seismic'!$E$5*D7)+D12)))*(P3-O7)+M4*(P4-O7)+M5*(P5-O7)+M6*(P6-O7) -> 1023.5432 | T7: =0.6*('Wind and Seismic'!$N$15) -> 41.419718 | U7: ='Wind and Seismic'!B30/'Wind and Seismic'!$E$5 -> 6.2508692 | V7: ='Wind and Seismic'!B21 -> 21.70695 | W7: 0 | X7: =0.6*('Wind and Seismic'!$N$13*(U3*(D7/('Wind and Seismic'!$E$5*$D$7+$D$12))*(V3-W7)+U4*(V4-W7)+U5*(V5-W7)+U6*(V6-W7)+U7*(V7-W7))) -> 640.6792
W8: 0
A9: R4 | B9: =('Wind and Seismic'!K37)*12 -> 0 | C9: ='Wind and Seismic'!K33 -> 0 | D9: =PI()/4*(B9^2-(B9-C9*2)^2) -> 0 | E9: =PI()/64*(B9^4-(B9-C9*2)^4) -> 0 | F9: =IF(B9=0,0,E9/(B9/2)) -> 0 | G9: =G8 -> 0 | H9: =IF(C9=0,0,(D9/(('Wind and Seismic'!E5*D7)+D12)*H3)) -> 0 | I9: ='Wind and Seismic'!K48 -> 0 | J9: =IF(C9=0,0,((D9/('Wind and Seismic'!$E$5*$D$7+$D$12))*J3)+G3) -> 0 | K9: =K8+H9 -> 0 | L9: ='Wind and Seismic'!K66+I9 -> 14.395 | M9: =0.6*'Wind and Seismic'!K44 -> 0 | N9: =N3*(D12/(('Wind and Seismic'!$E$5*D7)+D12))+M9 -> 11.15139 | O9: ='Wind and Seismic'!K34 -> 0 | P9: ='Wind and Seismic'!K45 -> 0 | Q9: =P9-O9 -> 0 | R9: =M9*(Q9) -> 0 | S9: =R9 -> 0 | T9: =0.6*('Wind and Seismic'!$N$15) -> 41.419718 | U9: ='Wind and Seismic'!K48 -> 0 | V9: ='Wind and Seismic'!K39 -> 0 | W9: 0
A10: R3 | B10: =('Wind and Seismic'!H37)*12 -> 48 | C10: ='Wind and Seismic'!H33 -> 0.625 | D10: =PI()/4*(B10^2-(B10-C10*2)^2) -> 93.020595 | E10: =PI()/64*(B10^4-(B10-C10*2)^4) -> 26101.361 | F10: =IF(B10=0,0,E10/(B10/2)) -> 1087.5567 | G10: =G9 -> 0 | H10: =IF(C10=0,0,(D10/(('Wind and Seismic'!E5*D7)+D12)*H3)) -> 0 | I10: ='Wind and Seismic'!H48 -> 9.260102 | J10: =IF(C10=0,0,((D10/('Wind and Seismic'!$E$5*$D$7+$D$12))*J3)+G9) -> 1291.5282 | K10: =K9+H10 -> 0 | L10: =L9+I10 -> 23.655102 | M10: =0.6*'Wind and Seismic'!H44 -> 2.4542314 | N10: =N9+M10 -> 13.605621 | O10: ='Wind and Seismic'!H34 -> 86.8278 | P10: ='Wind and Seismic'!H45 -> 101.60439 | Q10: =P10-O10 -> 14.77659 | R10: =M10*(Q10) -> 36.265172 | S10: =R10+(M3*(D12/(('Wind and Seismic'!$E$5*D7)+D12)))*(P3-O10)+M9*(P9-O10) -> 591.5765 | T10: =0.6*('Wind and Seismic'!$N$15) -> 41.419718 | U10: ='Wind and Seismic'!H48 -> 9.260102 | V10: ='Wind and Seismic'!H39 -> 101.4554 | W10: 86.8278 | X10: =0.6*('Wind and Seismic'!$N$13*((U3*(D10/('Wind and Seismic'!$E$5*$D$7+$D$12))*(V3-W10)+U9*(V9-W10)+U10*(V10-W10)))) -> 611.42275
A11: R2 | B11: =('Wind and Seismic'!E37)*12 -> 48 | C11: ='Wind and Seismic'!E33 -> 0.625 | D11: =PI()/4*(B11^2-(B11-C11*2)^2) -> 93.020595 | E11: =PI()/64*(B11^4-(B11-C11*2)^4) -> 26101.361 | F11: =IF(B11=0,0,E11/(B11/2)) -> 1087.5567 | G11: =G10 -> 0 | H11: =IF(C11=0,0,(D11/(('Wind and Seismic'!E5*D7)+D12)*H3)) -> 0 | I11: ='Wind and Seismic'!E48 -> 13.741733 | J11: =J10+G11 -> 1291.5282 | K11: =K10+H11 -> 0 | L11: =L10+I11 -> 37.396835 | M11: =0.6*'Wind and Seismic'!E44 -> 3.2910258 | N11: =N10+M11 -> 16.896647 | O11: ='Wind and Seismic'!E34 -> 43.4139 | P11: ='Wind and Seismic'!E45 -> 65.647849 | Q11: =P11-O11 -> 22.233949 | R11: =M11*(Q11) -> 73.172499 | S11: =R11+(M3*(D12/(('Wind and Seismic'!$E$5*D7)+D12)))*(P3-O11)+M9*(P9-O11)+M10*(P10-O11) -> 1255.4221 | T11: =0.6*('Wind and Seismic'!$N$15) -> 41.419718 | U11: ='Wind and Seismic'!E48 -> 13.741733 | V11: ='Wind and Seismic'!E39 -> 65.12085 | W11: 43.4139 | X11: =0.6*('Wind and Seismic'!$N$13*((U3*(D11/('Wind and Seismic'!$E$5*$D$7+$D$12))*(V3-W11)+U9*(V9-W11)+U10*(V10-W11))+U11*(V11-W11))) -> 1149.8204
A12: R1 | B12: =('Wind and Seismic'!B37)*12 -> 48 | C12: ='Wind and Seismic'!B33 -> 0.625 | D12: =PI()/4*(B12^2-(B12-C12*2)^2) -> 93.020595 | E12: =PI()/64*(B12^4-(B12-C12*2)^4) -> 26101.361 | F12: =IF(B12=0,0,E12/(B12/2)) -> 1087.5567 | G12: =G11 -> 0 | H12: =IF(C12=0,0,(D12/(('Wind and Seismic'!E5*D7)+D12)*H3)) -> 0 | I12: ='Wind and Seismic'!B48 -> 13.741733 | J12: =J11+G12 -> 1291.5282 | K12: =K11+H12 -> 0 | L12: =L11+I12 -> 51.138568 | M12: =0.6*'Wind and Seismic'!B44 -> 2.7454768 | N12: =N11+M12 -> 19.642124 | O12: ='Wind and Seismic'!B34 -> 0 | P12: ='Wind and Seismic'!B45 -> 22.513016 | Q12: =P12-O12 -> 22.513016 | R12: =M12*(Q12) -> 61.808963 | S12: =R12+(M3*(D12/(('Wind and Seismic'!$E$5*D7)+D12)))*(P3-O12)+M9*(P9-O12)+M10*(P10-O12)+M11*(P11-O12) -> 2050.7804 | T12: =0.6*('Wind and Seismic'!$N$15) -> 41.419718 | U12: ='Wind and Seismic'!B48 -> 13.741733 | V12: ='Wind and Seismic'!B39 -> 21.70695 | W12: 0 | X12: =0.6*('Wind and Seismic'!$N$13*((U3*(D12/('Wind and Seismic'!$E$5*$D$7+$D$12))*(V3-W12)+U9*(V9-W12)+U10*(V10-W12))+U11*(V11-W12)+U12*(V12-W12))) -> 1693.7042
A14: Allowable compressive stress for column
A15: FY | B15: 36000 | C15: psi
A16: k | B16: 1
A18: (R/t)c | B18: =VLOOKUP(B15,P21:Q27,2,FALSE) -> 334
A19: E | B19: 29000000 | C19: psi
A20: Segement | B20: Radius(in) | C20: Thickness(in) | D20: R/t | E20: A (in2) | F20: I (in4) | G20: r(in) | H20: C0 | I20: Fl | J20: KL/r | K20: C'c | L20: kf | M20: Fa | N20: Fb | P20: Fy | Q20: (R/t)c
A21: {=A3:A12} -> Tank | B21: - | C21: - | D21: - | E21: - | F21: - | G21: - | H21: - | I21: - | J21: - | K21: - | L21: - | M21: - | N21: {=I21:I30} -> - | P21: 30000 | Q21: 403
A22: C4 | B22: {=B4:B12/2} -> 0 | C22: {=C4:C12} -> 0 | D22: =IF(B22=0,0,B22/C22) -> 0 | E22: {=D4:D12} -> 0 | F22: {=E4:E12} -> 0 | G22: =IF(B22=0,0,SQRT(F22/E22)) -> 0 | H22: =IF(B22=0,0,MAX(0.125,1022/(195+D22))) -> 0 | I22: =IF(B22=0,0,IF(D22<$B$18,MIN(233*$B$15/2/(166+D22),$B$15/2),H22*$B$19/2/D22)/1000) -> 0 | J22: =IF(B22=0,0,$B$16*12*'Wind and Seismic'!K17/G22) -> 0 | K22: =IF(B22=0,0,SQRT(PI()^2*$B$19/I22/1000)) -> 0 | L22: =IF(B22=0,0,IF(J22>K22,0.5*(K22/J22)^2,IF(J22<25,1,1-0.5*(J22/K22)^2))) -> 0 | M22: =IF(B22=0,0,L22*I22) -> 0 | N22: 0 | P22: 32000 | Q22: 377
A23: C3 | B23: 15 | C23: 0.375 | D23: =IF(B23=0,0,B23/C23) -> 40 | E23: 34.901131 | F23: 3829.4448 | G23: =IF(B23=0,0,SQRT(F23/E23)) -> 10.474858 | H23: =IF(B23=0,0,MAX(0.125,1022/(195+D23))) -> 4.3489362 | I23: =IF(B23=0,0,IF(D23<$B$18,MIN(233*$B$15/2/(166+D23),$B$15/2),H23*$B$19/2/D23)/1000) -> 18 | J23: =IF(B23=0,0,$B$16*12*'Wind and Seismic'!H17/G23) -> 54.030974 | K23: =IF(B23=0,0,SQRT(PI()^2*$B$19/I23/1000)) -> 126.09928 | L23: =IF(B23=0,0,IF(J23>K23,0.5*(K23/J23)^2,IF(J23<25,1,1-0.5*(J23/K23)^2))) -> 0.9082026 | M23: =IF(B23=0,0,L23*I23) -> 16.347647 | N23: 18 | P23: 34000 | Q23: 354
A24: C2 | B24: 15 | C24: 0.375 | D24: =IF(B24=0,0,B24/C24) -> 40 | E24: 34.901131 | F24: 3829.4448 | G24: =IF(B24=0,0,SQRT(F24/E24)) -> 10.474858 | H24: =IF(B24=0,0,MAX(0.125,1022/(195+D24))) -> 4.3489362 | I24: =IF(B24=0,0,IF(D24<$B$18,MIN(233*$B$15/2/(166+D24),$B$15/2),H24*$B$19/2/D24)/1000) -> 18 | J24: =IF(B24=0,0,$B$16*12*'Wind and Seismic'!E17/G24) -> 49.734974 | K24: =IF(B24=0,0,SQRT(PI()^2*$B$19/I24/1000)) -> 126.09928 | L24: =IF(B24=0,0,IF(J24>K24,0.5*(K24/J24)^2,IF(J24<25,1,1-0.5*(J24/K24)^2))) -> 0.92221989 | M24: =IF(B24=0,0,L24*I24) -> 16.599958 | N24: 18 | P24: 36000 | Q24: 334
A25: C1 | B25: 15 | C25: 0.375 | D25: =IF(B25=0,0,B25/C25) -> 40 | E25: 34.901131 | F25: 3829.4448 | G25: =IF(B25=0,0,SQRT(F25/E25)) -> 10.474858 | H25: =IF(B25=0,0,MAX(0.125,1022/(195+D25))) -> 4.3489362 | I25: =IF(B25=0,0,IF(D25<$B$18,MIN(233*$B$15/2/(166+D25),$B$15/2),H25*$B$19/2/D25)/1000) -> 18 | J25: =IF(B25=0,0,$B$16*12*'Wind and Seismic'!B17/G25) -> 49.734974 | K25: =IF(B25=0,0,SQRT(PI()^2*$B$19/I25/1000)) -> 126.09928 | L25: =IF(B25=0,0,IF(J25>K25,0.5*(K25/J25)^2,IF(J25<25,1,1-0.5*(J25/K25)^2))) -> 0.92221989 | M25: =IF(B25=0,0,L25*I25) -> 16.599958 | N25: 18 | P25: 38000 | Q25: 316
A26: 0 | B26: 0 | C26: 0 | E26: 0 | F26: 0 | N26: 0 | P26: 40000 | Q26: 299
A27: R4 | B27: 0 | C27: 0 | D27: =IF(B27=0,0,B27/C27) -> 0 | E27: 0 | F27: 0 | G27: =IF(B27=0,0,SQRT(F27/E27)) -> 0 | H27: =IF(B27=0,0,MAX(0.125,1022/(195+D27))) -> 0 | I27: =IF(B27=0,0,IF(D27<$B$18,MIN(233*$B$15/2/(166+D27),$B$15/2),H27*$B$19/2/D27)/1000) -> 0 | J27: =IF(B27=0,0,$B$16*12*'Wind and Seismic'!K35/G27) -> 0 | K27: =IF(B27=0,0,SQRT(PI()^2*$B$19/I27/1000)) -> 0 | L27: =IF(B27=0,0,IF(J27>K27,0.5*(K27/J27)^2,IF(J27<25,1,1-0.5*(J27/K27)^2))) -> 0 | M27: =IF(B27=0,0,L27*I27) -> 0 | N27: 0
A28: R3 | B28: 24 | C28: 0.625 | D28: =IF(B28=0,0,B28/C28) -> 38.4 | E28: 93.020595 | F28: 26101.361 | G28: =IF(B28=0,0,SQRT(F28/E28)) -> 16.751049 | H28: =IF(B28=0,0,MAX(0.125,1022/(195+D28))) -> 4.3787489 | I28: =IF(B28=0,0,IF(D28<$B$18,MIN(233*$B$15/2/(166+D28),$B$15/2),H28*$B$19/2/D28)/1000) -> 18 | J28: =IF(B28=0,0,$B$16*12*'Wind and Seismic'!H35/G28) -> 20.957636 | K28: =IF(B28=0,0,SQRT(PI()^2*$B$19/I28/1000)) -> 126.09928 | L28: =IF(B28=0,0,IF(J28>K28,0.5*(K28/J28)^2,IF(J28<25,1,1-0.5*(J28/K28)^2))) -> 1 | M28: =IF(B28=0,0,L28*I28) -> 18 | N28: 18
A29: R2 | B29: 24 | C29: 0.625 | D29: =IF(B29=0,0,B29/C29) -> 38.4 | E29: 93.020595 | F29: 26101.361 | G29: =IF(B29=0,0,SQRT(F29/E29)) -> 16.751049 | H29: =IF(B29=0,0,MAX(0.125,1022/(195+D29))) -> 4.3787489 | I29: =IF(B29=0,0,IF(D29<$B$18,MIN(233*$B$15/2/(166+D29),$B$15/2),H29*$B$19/2/D29)/1000) -> 18 | J29: =IF(B29=0,0,$B$16*12*'Wind and Seismic'!E35/G29) -> 31.100547 | K29: =IF(B29=0,0,SQRT(PI()^2*$B$19/I29/1000)) -> 126.09928 | L29: =IF(B29=0,0,IF(J29>K29,0.5*(K29/J29)^2,IF(J29<25,1,1-0.5*(J29/K29)^2))) -> 0.96958549 | M29: =IF(B29=0,0,L29*I29) -> 17.452539 | N29: 18
A30: R1 | B30: 24 | C30: 0.625 | D30: =IF(B30=0,0,B30/C30) -> 38.4 | E30: 93.020595 | F30: 26101.361 | G30: =IF(B30=0,0,SQRT(F30/E30)) -> 16.751049 | H30: =IF(B30=0,0,MAX(0.125,1022/(195+D30))) -> 4.3787489 | I30: =IF(B30=0,0,IF(D30<$B$18,MIN(233*$B$15/2/(166+D30),$B$15/2),H30*$B$19/2/D30)/1000) -> 18 | J30: =IF(B30=0,0,$B$16*12*'Wind and Seismic'!B35/G30) -> 31.100547 | K30: =IF(B30=0,0,SQRT(PI()^2*$B$19/I30/1000)) -> 126.09928 | L30: =IF(B30=0,0,IF(J30>K30,0.5*(K30/J30)^2,IF(J30<25,1,1-0.5*(J30/K30)^2))) -> 0.96958549 | M30: =IF(B30=0,0,L30*I30) -> 17.452539 | N30: 18
A32: {=A20:A30} -> Segement | B32: fa | C32: fb | D32: check
A33: Tank | B33: - | C33: - | D33: -
A34: C4 | B34: =IF(D4=0,0,(J4+K4+L4)/D4) -> 0 | C34: =IF(F4=0,0,S4*12/F4) -> 0 | D34: =IF(B34+C34=0,"NA",B34/M22+C34/N22) -> NA
A35: C3 | B35: =IF(D5=0,0,(J5+K5+L5)/D5) -> 14.725737 | C35: =IF(F5=0,0,S5*12/F5) -> 12.620132 | D35: =IF(B35+C35=0,"NA",B35/M23+C35/N23) -> 1.6019047
A36: C2 | B36: =IF(D6=0,0,(J6+K6+L6)/D6) -> 14.918568 | C36: =IF(F6=0,0,S6*12/F6) -> 28.433715 | D36: =IF(B36+C36=0,"NA",B36/M24+C36/N24) -> 2.478362
A37: C1 | B37: =IF(D7=0,0,(J7+K7+L7)/D7) -> 15.09767 | C37: =IF(F7=0,0,S7*12/F7) -> 48.11083 | D37: =IF(B37+C37=0,"NA",B37/M25+C37/N25) -> 3.5823244
A38: 0 | B38: =IF(D8=0,0,(J8+K8+L8)/D8) -> 0 | C38: =IF(F8=0,0,S8*12/F8) -> 0 | D38: =IF(B38+C38=0,"NA",B38/M26+C38/N26) -> NA
A39: R4 | B39: =IF(D9=0,0,(J9+K9+L9)/D9) -> 0 | C39: =IF(F9=0,0,S9*12/F9) -> 0 | D39: =IF(B39+C39=0,"NA",B39/M27+C39/N27) -> NA
A40: R3 | B40: =IF(D10=0,0,(J10+K10+L10)/D10) -> 14.138624 | C40: =IF(F10=0,0,S10*12/F10) -> 6.5274003 | D40: =IF(B40+C40=0,"NA",B40/M28+C40/N28) -> 1.1481125
A41: R2 | B41: =IF(D11=0,0,(J11+K11+L11)/D11) -> 14.286352 | C41: =IF(F11=0,0,S11*12/F11) -> 13.852211 | D41: =IF(B41+C41=0,"NA",B41/M29+C41/N29) -> 1.5881503
A42: R1 | B42: =IF(D12=0,0,(J12+K12+L12)/D12) -> 14.43408 | C42: =IF(F12=0,0,S12*12/F12) -> 22.628121 | D42: =IF(B42+C42=0,"NA",B42/M30+C42/N30) -> 2.0841654

Sheet Tanks Information
A1: Volumn (Gal.) | B1: Diameter (ft) | C1: Centroied (ft) | D1: tank height (ft) | E1: Weight of water (Kips) | F1: Weight of steel (Kips) | G1: Total weight (Kips) | H1: projected area (ft2)
A2: 50K-DE | B2: 24 | C2: 11.5 | D2: 23.001 | E2: 421 | F2: 25.0264 | G2: =F2+E2 -> 446.0264 | H2: 470
A3: 100K-DE | B3: 32 | C3: 12.6 | D3: 25.2156 | E3: 879 | F3: 40.3865 | G3: =F3+E3 -> 919.3865 | H3: 612
A4: 200K-DE | B4: 38 | C4: 16 | D4: 31.5884 | E4: 1729 | F4: 63.6953 | G4: =F4+E4 -> 1792.6953 | H4: 982
A5: 250K-TORO | B5: 43 | C5: 14.1 | D5: 29.6777 | E5: 2139 | F5: 69.913 | G5: =F5+E5 -> 2208.913 | H5: 1067
A6: 300K-TORO | B6: 43 | C6: 16 | D6: 34.5944 | E6: 2581 | F6: 84.741 | G6: =F6+E6 -> 2665.741 | H6: 1278
A7: 400K-TORO | B7: 50 | C7: 15.8 | D7: 34.3946 | E7: 3353 | F7: 83.7002 | G7: =F7+E7 -> 3436.7002 | H7: 1437
A8: 500K-TORO | B8: 56 | C8: 15 | D8: 34.8552 | E8: 4199 | F8: 133.145 | G8: =F8+E8 -> 4332.145 | H8: 1617
