Workbook

Sheet Wind and Seismic
A1: wind load paramets | P1: seismic base shear
A2: kzt | B2: 1 | P2: Ss | Q2: 0.1 | R2: g
A3: kd | B3: 1 | P3: S1 | Q3: 0.033 | R3: g
A4: I | B4: 1.15 | P4: SDS | Q4: =2/3*1.6*Q2 -> 0.10666667 | R4: g
A5: V | B5: 90 | C5: mph | P5: SD1 | Q5: =2/3*2.4*Q3 -> 0.0528 | R5: g
A6: exposure | B6: C | P6: Ri | Q6: 3
A7: a | B7: =IF(B6="C",9.5,11.5) -> 9.5 | P7: IE | Q7: 1.5
A8: Zg | B8: =IF(B6="C",900,700) -> 900 | C8: ft | P8: TL | Q8: 12 | R8: sec
A9: G | B9: 1 | P9: Ti | Q9: 4 | R9: sec
A10: Cf | B10: 0.6 | P10: Ts | Q10: =Q5/Q4 -> 0.495 | R10: sec
A11: λ | B11: 0.6 | P11: Sai | Q11: =IF(Q9<Q10,Q4,IF(Q9>Q8,Q5*Q8/Q9^2,Q5/Q9)) -> 0.0132 | R11: g
A12: (0.00256 Kzt Kd I V2) | B12: =0.00256*B2*B3*B4*B5^2 -> 23.8464 | P12: λ | Q12: 0.7
A13: cylinder weight 1 | D13: cylinder weight 2 | G13: cylinder weight 3 | J13: cylinder weight 4 | P13: Ai | Q13: =MAX(Q12*Q11*Q7/Q6,0.36*Q3*Q7/Q6) -> 0.00594 | R13: ft/s2
A14: Sequence number | B14: 6 | D14: Sequence number | E14: 7 | G14: Sequence number | H14: 8 | J14: Sequence number | K14: 9 | P14: COM | Q14: =(B29+E29+H29+K29+H54+E54+B54+B68*B72+K54+N54)/B81 -> 151.78009
A15: Thickness | B15: 0.6875 | C15: in | D15: Thickness | E15: 0.625 | F15: in | G15: Thickness | H15: 0.56253 | I15: in | J15: Thickness | K15: 0 | L15: in | P15: V | Q15: =Q13*B81 -> 13.879793 | R15: kips
A16: hi | B16: 25 | C16: ft | D16: hi | E16: =B18 -> 52.07 | G16: hi | H16: =E18 -> 92.07 | I16: ft | J16: hi | K16: =H18 -> 132.07 | L16: ft | P16: Seismic base moment | Q16: =Q15*Q14 -> 2106.6763 | R16: kips-ft
A17: Height of the cylinder | B17: 27.07 | C17: ft | D17: Height of the cylinder | E17: 40 | F17: ft | G17: Height of the cylinder | H17: 40 | I17: ft | J17: Height of the cylinder | K17: 0 | L17: ft
A18: hf | B18: =B16+B17 -> 52.07 | C18: ft | D18: hf | E18: =E16+E17 -> 92.07 | G18: hf | H18: =H16+H17 -> 132.07 | I18: ft | J18: hf | K18: =K16+K17 -> 132.07 | L18: ft
A19: Diameter of the cylinder | B19: 9 | C19: ft | D19: Diameter of the cylinder | E19: 9 | F19: ft | G19: Diameter of the cylinder | H19: 9 | I19: ft | J19: Diameter of the cylinder | K19: 0 | L19: ft
A20: Awind | B20: =IF(B15=0,0,B19*B17) -> 243.63 | C20: ft2 | D20: Awind | E20: =IF(E15=0,0,E19*E17) -> 360 | F20: ft2 | G20: Awind | H20: =IF(H15=0,0,H19*H17) -> 360 | I20: ft2 | J20: Awind | K20: =IF(K15=0,0,K19*K17) -> 0 | L20: ft2
A21: Centroid | B21: =B16+B17/2 -> 38.535 | C21: ft | D21: Centroid | E21: =E16+E17/2 -> 72.07 | F21: ft | G21: Centroid | H21: =H16+H17/2 -> 112.07 | I21: ft | J21: Centroid | K21: =K16+K17/2 -> 132.07 | L21: ft
A22: kzi | B22: =2.01*(MAX(B16,15)/$B$8)^(2/$B$7) -> 0.94526467 | D22: kzi | E22: =2.01*(MAX(E16,15)/$B$8)^(2/$B$7) -> 1.1031565 | G22: kzi | H22: =2.01*(MAX(H16,15)/$B$8)^(2/$B$7) -> 1.243795 | J22: kzi | K22: =2.01*(MAX(K16,15)/$B$8)^(2/$B$7) -> 1.341947
A23: kzf | B23: =2.01*(MAX(B18,15)/$B$8)^(2/$B$7) -> 1.1031565 | D23: kzf | E23: =2.01*(MAX(E18,15)/$B$8)^(2/$B$7) -> 1.243795 | G23: kzf | H23: =2.01*(MAX(H18,15)/$B$8)^(2/$B$7) -> 1.341947 | J23: kzf | K23: =2.01*(MAX(K18,15)/$B$8)^(2/$B$7) -> 1.341947
A24: qzi | B24: =B22*$B$12 -> 22.541159 | C24: psf | D24: qzi | E24: =E22*$B$12 -> 26.306311 | F24: psf | G24: qzi | H24: =H22*$B$12 -> 29.660034 | I24: psf | J24: qzi | K24: =K22*$B$12 -> 32.000604 | L24: psf
A25: qzf | B25: =B23*$B$12 -> 26.306311 | C25: psf | D25: qzf | E25: =E23*$B$12 -> 29.660034 | F25: psf | G25: qzf | H25: =H23*$B$12 -> 32.000604 | I25: psf | J25: qzf | K25: =K23*$B$12 -> 32.000604 | L25: psf
A26: F | B26: =MAX((B24+B25)/2*$B$9*$B$10,30*$B$10)*B20/1000 -> 4.38534 | C26: kips | D26: F | E26: =MAX((E24+E25)/2*$B$9*$B$10,30*$B$10)*E20/1000 -> 6.48 | F26: kips | G26: F | H26: =MAX((H24+H25)/2*$B$9*$B$10,30*$B$10)*H20/1000 -> 6.659349 | I26: kips | J26: F | K26: =MAX((K24+K25)/2*$B$9*$B$10,30*$B$10)*K20/1000 -> 0 | L26: kips | P26: Wind base shear | Q26: =K26+H26+E26+B26 -> 17.524689 | R26: kips
A27: F location | B27: =B16+((B24*B17^2/2+2/3*0.5*B17^2*(B25-B24))/(B24*B17+0.5*B17*(B25-B24))) -> 38.882758 | C27: ft | D27: F location | E27: =E16+((E24*E17^2/2+2/3*0.5*E17^2*(E25-E24))/(E24*E17+0.5*E17*(E25-E24))) -> 72.469493 | F27: ft | G27: F location | H27: =H16+((H24*H17^2/2+2/3*0.5*H17^2*(H25-H24))/(H24*H17+0.5*H17*(H25-H24))) -> 112.32306 | I27: ft | J27: F location | K27: =IF(K15=0,0,K16+((K24*K17^2/2+2/3*0.5*K17^2*(K25-K24))/(K24*K17+0.5*K17*(K25-K24)))) -> 0 | L27: ft
A28: Wind moment At base | B28: =B27*B26 -> 170.51411 | C28: kips-ft | D28: Wind moment At base | E28: =E27*E26 -> 469.60231 | F28: kips-ft | G28: Wind moment At base | H28: =H27*H26 -> 747.99845 | I28: kips-ft | J28: Wind moment At base | K28: =K27*K26 -> 0 | L28: kips-ft | P28: Wind base moment | Q28: =K28+H28+E28+B28 -> 1388.1149 | R28: kips-ft
A29: Center of mass x weight | B29: =B30*B21 -> 822.71629 | D29: Center of mass x weight | E29: =E30*E21 -> 2068.1459 | G29: Center of mass x weight | H29: =H30*H21 -> 2896.2383 | J29: Center of mass x weight | K29: =K30*K21 -> 0
A30: Weight | B30: =PI()/4*(B19^2-(B19-2*B15/12)^2)*B17*490/1000 -> 21.349845 | C30: kips | D30: Weight | E30: =PI()/4*(E19^2-(E19-2*E15/12)^2)*E17*490/1000 -> 28.696349 | F30: kips | G30: Weight | H30: =PI()/4*(H19^2-(H19-2*H15/12)^2)*H17*490/1000 -> 25.843118 | I30: kips | J30: Weight | K30: =PI()/4*(K19^2-(K19-2*K15/12)^2)*K17*490/1000 -> 0 | L30: kips | P30: weight of steel | Q30: =K30+H30+E30+B30 -> 75.889312 | R30: kips
A31: frustum weight 1 | D31: frustum weight 2 | G31: frustum weight 3 | J31: frustum weight 4 | M31: frustum weight 5
A32: Sequence number | B32: 1 | D32: Sequence number | E32: 2 | G32: Sequence number | H32: 3 | J32: Sequence number | K32: 4 | M32: Sequence number | N32: 5
A33: Thickness | B33: 0.5 | C33: in | D33: Thickness | E33: =9/16 -> 0.5625 | F33: in | G33: Thickness | H33: =5/8 -> 0.625 | I33: in | J33: Thickness | K33: 0.75 | L33: in | M33: Thickness | N33: 0 | O33: in
A34: hi | B34: 0 | C34: ft | D34: hi | E34: =B36 -> 7 | F34: ft | G34: hi | H34: =E36 -> 14 | I34: ft | J34: hi | K34: =H36 -> 21 | L34: ft | M34: hi | N34: 0 | O34: ft
A35: Height of the cone | B35: 7 | C35: ft | D35: Height of the cone | E35: 7 | F35: ft | G35: Height of the cone | H35: 7 | I35: ft | J35: Height of the cone | K35: 4 | L35: ft | M35: Height of the cone | N35: 0 | O35: ft
A36: hf | B36: =B35+B34 -> 7 | C36: ft | D36: hf | E36: =E35+E34 -> 14 | F36: ft | G36: hf | H36: =H35+H34 -> 21 | I36: ft | J36: hf | K36: =K35+K34 -> 25 | L36: ft | M36: hf | N36: =N35+N34 -> 0 | O36: ft
A37: Bottom diameter | B37: 25 | C37: ft | D37: Bottom diameter | E37: =B38 -> 20.52 | F37: ft | G37: Bottom diameter | H37: =E38 -> 16.04 | I37: ft | J37: Bottom diameter | K37: =H38 -> 11.56 | L37: ft | M37: Bottom diameter | N37: 0 | O37: ft
A38: Top diameter | B38: =$B$37-($B$37-9)/(25)*(B35) -> 20.52 | C38: ft | D38: Top diameter | E38: =$B$37-($B$37-9)/(25)*(B35+E35) -> 16.04 | F38: ft | G38: Top diameter | H38: =$B$37-($B$37-9)/(25)*(B35+E35+H35) -> 11.56 | I38: ft | J38: Top diameter | K38: =$B$37-($B$37-9)/(25)*(B35+E35+H35+K35) -> 9 | L38: ft | M38: Top diameter | N38: 0 | O38: ft
A39: S1 | B39: =ROUND(PI()*B38^2/4,2) -> 330.71 | C39: ft2 | D39: S1 | E39: =ROUND(PI()*E38^2/4,2) -> 202.07 | F39: ft2 | G39: S1 | H39: =ROUND(PI()*H38^2/4,2) -> 104.96 | I39: ft2 | J39: S1 | K39: =ROUND(PI()*K38^2/4,2) -> 63.62 | L39: ft2 | M39: S1 | N39: =ROUND(PI()*N38^2/4,2) -> 0 | O39: ft2
A40: S2 | B40: =ROUND(PI()*B37^2/4,2) -> 490.87 | C40: ft2 | D40: S2 | E40: =ROUND(PI()*E37^2/4,2) -> 330.71 | F40: ft2 | G40: S2 | H40: =ROUND(PI()*H37^2/4,2) -> 202.07 | I40: ft2 | J40: S2 | K40: =ROUND(PI()*K37^2/4,2) -> 104.96 | L40: ft2 | M40: S2 | N40: =ROUND(PI()*N37^2/4,2) -> 0 | O40: ft2
...

Sheet Loads
A1: Snow Load | E1: Roof Live Load | I1: Live Load | M1: Load Combination | Q1: P | S1: M
A2: Diameter of tank | B2: 43.67 | C2: ft | E2: Min Roof Live Load | F2: 15 | G2: psf | I2: Live Load | J2: 0 | K2: kips | M2: D | Q2: ='Wind and Seismic'!B81 -> 2336.6655 | S2: 0
A3: Height to consider | B3: 7.1631 | C3: ft | E3: Area to consider | F3: =B4 -> 982.72969 | G3: ft2 | M3: D + L | Q3: ='Wind and Seismic'!B81+J2 -> 2336.6655 | S3: 0
A4: Area to consider | B4: =PI()*B2*B3 -> 982.72969 | C4: ft2 | E4: Roof Live Load | F4: =F2*F3/1000 -> 14.740945 | G4: kips | M4: D + (Lr or S) | Q4: ='Wind and Seismic'!B81+(MAX(B11,F4)) -> 2372.3268 | S4: 0
A5: Ground snow load | B5: 40 | C5: psf | M5: D + 0.75L + 0.75(Lr or S) | Q5: ='Wind and Seismic'!B81+0.75*J2+0.75*(MAX(B11,F4)) -> 2363.4115 | S5: 0
A6: Exposure Factor | B6: C | M6: D + 0.6(W or E) | Q6: ='Wind and Seismic'!B81 -> 2336.6655 | S6: =0.6*(MAX('Wind and Seismic'!B78,'Wind and Seismic'!Q16)) -> 3383.4304
A7: Ce | B7: =IF(B6="C",0.9,0.8) -> 0.9 | M7: D + 0.75L + 0.75(0.6W or 0.6E) + 0.75(Lr or S) | Q7: ='Wind and Seismic'!B81+(0.75*J2)+(0.75*(MAX(B11,F4))) -> 2363.4115 | S7: =0.45*(MAX('Wind and Seismic'!B78,'Wind and Seismic'!Q16)) -> 2537.5728
A8: Ct | B8: 1.2 | M8: 0.6D + 0.6(W or E) | Q8: =0.6*'Wind and Seismic'!B81 -> 1401.9993 | S8: =0.6*(MAX('Wind and Seismic'!B78,'Wind and Seismic'!Q16)) -> 3383.4304
A9: Importance Factor | B9: RC IV
A10: Is | B10: =IF(B9="RC II",1,IF(B9="RC III",1.1,1.2)) -> 1.2
A11: Snow load | B11: =0.7*B4*B5*B7*B8*B10/1000 -> 35.661295 | C11: kips
A14: 0.6D + 0.6(W or E) | E14: D + 0.75L + 0.75(0.6W or 0.6E) + 0.75(Lr or S) | I14: D + 0.6(W or E)
A15: =Q8 -> 1401.9993 | B15: kips | E15: =Q7 -> 2363.4115 | F15: kips | I15: =Q6 -> 2336.6655 | K15: kips
A16: =S8 -> 3383.4304 | B16: ft-kips | E16: =S7 -> 2537.5728 | F16: ft-kips | I16: =S6 -> 3383.4304 | K16: ft-kips
A17: fa | B17: fb | C17: check | E17: fa | F17: fb | G17: check | I17: fa | K17: fb | L17: check
A18: {=Q8/(IF('Design Table'!$B$4:$B$12=0,0,'Design Table'!$D$4:$D$12))} -> #DIV/0! | B18: {=S8*12/(IF('Design Table'!$B$4:$B$12=0,0,'Design Table'!$F$4:$F$12))} -> #DIV/0! | C18: {=(A18:A26/'Design Table'!$M$22:$M$30)+(B18:B26/'Design Table'!$N$22:$N$30)} -> #DIV/0! | E18: {=Q7/(IF('Design Table'!$B$4:$B$12=0,0,'Design Table'!$D$4:$D$12))} -> #DIV/0! | F18: {=S7*12/(IF('Design Table'!$B$4:$B$12=0,0,'Design Table'!$F$4:$F$12))} -> #DIV/0! | G18: {=(E18:E26/'Design Table'!$M$22:$M$30)+(F18:F26/'Design Table'!$N$22:$N$30)} -> #DIV/0! | I18: {=Q6/(IF('Design Table'!$B$4:$B$12=0,0,'Design Table'!$D$4:$D$12))} -> #DIV/0! | K18: {=S6*12/(IF('Design Table'!$B$4:$B$12=0,0,'Design Table'!$F$4:$F$12))} -> #DIV/0! | L18: {=(I18:I26/'Design Table'!$M$22:$M$30)+(K18:K26/'Design Table'!$N$22:$N$30)} -> #DIV/0!
A19: 7.3840812 | B19: 8.0029011 | C19: 0.99960846 | E19: 12.447668 | F19: 6.0021758 | G19: 1.2172745 | I19: 12.306802 | K19: 8.0029011 | L19: 1.3327254
A20: 6.6498941 | B20: 7.2155278 | C20: 0.84868469 | E20: 11.210017 | F20: 5.4116458 | G20: 1.0243283 | I20: 11.083157 | K20: 7.2155278 | L20: 1.1249817
A21: 6.0488792 | B21: 6.5709914 | C21: 0.73584454 | E21: 10.19686 | F21: 4.9282435 | G21: 0.88192067 | I21: 10.081465 | K21: 6.5709914 | L21: 0.97097821
A22: #DIV/0! | B22: #DIV/0! | C22: #DIV/0! | E22: #DIV/0! | F22: #DIV/0! | G22: #DIV/0! | I22: #DIV/0! | K22: #DIV/0! | L22: #DIV/0!
A23: 4.3127273 | B23: 3.640488 | C23: 0.49016382 | E23: 7.2701528 | F23: 2.730366 | G23: 0.61634099 | I23: 7.1878788 | K23: 3.640488 | L23: 0.66736201
A24: 3.7217293 | B24: 2.2543961 | C24: 0.45595244 | E24: 6.2738818 | F24: 1.6907971 | G24: 0.60767043 | I24: 6.2028822 | K24: 2.2543961 | L24: 0.64525364
A25: 3.2293121 | B25: 1.5261115 | C25: 0.43640138 | E25: 5.4437924 | F25: 1.1445836 | G25: 0.60460996 | I25: 5.3821868 | K25: 1.5261115 | L25: 0.63396896
A26: 2.9801018 | B26: 1.1545378 | C26: 0.4594044 | E26: 5.0236877 | F26: 0.86590337 | G26: 0.65439901 | I26: 4.9668363 | K26: 1.1545378 | L26: 0.68015268

Sheet Design Table
G1: Gravity Loads (per segemnet) | J1: Gravity Loads (cumulative) | M1: Wind Load (per segement) | T1: Seismic Load (per segment)
A2: Segement | B2: Diameter(in) | C2: Thickness(in) | D2: A (in2) | E2: I (in4) | F2: S (in3) | G2: Wwater | H2: Wsnow | I2: Wself-weight | J2: Wwater | K2: Wsnow | L2: Wself-weight | M2: Fwind | N2: V wind | O2: Base Elevation | P2: load location | Q2: Arm length | R2: F x Arm | S2: Mwind | T2: Fseismic | U2: Weight | V2: Centroid | W2: Base Elevation | X2: Mseismic
A3: Tank | B3: 0 | C3: 0 | D3: - | E3: - | F3: - | G3: ='Wind and Seismic'!$B$70 -> 2122 | I3: ='Wind and Seismic'!$B$71 -> 107.6857 | J3: {=G3:I3} -> 2122 | K3: 0 | L3: 107.6857 | M3: ='Wind and Seismic'!B67*0.6 -> 16.003543 | N3: =M3 -> 16.003543 | O3: ='Wind and Seismic'!B61 -> 132.07 | P3: ='Wind and Seismic'!B68 -> 156.31 | Q3: =P3-O3 -> 24.24 | R3: =M3*(Q3) -> 387.92588 | S3: =R3 -> 387.92588 | T3: =0.6*('Wind and Seismic'!$Q$15) -> 8.3278759 | U3: ='Wind and Seismic'!B72 -> 2229.6857 | V3: ='Wind and Seismic'!B68 -> 156.31 | W3: {=O3:O12} -> 132.07
A4: 9 | B4: =('Wind and Seismic'!K19)*12 -> 0 | C4: ='Wind and Seismic'!K15 -> 0 | D4: =PI()/4*(B4^2-(B4-C4*2)^2) -> 0 | E4: =PI()/64*(B4^4-(B4-C4*2)^4) -> 0 | F4: =IF(B4=0,0,E4/(B4/2)) -> 0 | G4: 0 | H4: 0 | I4: ='Wind and Seismic'!K30 -> 0 | J4: =J3+G4 -> 2122 | K4: =K3+H4 -> 0 | L4: =L3+I4 -> 107.6857 | M4: ='Wind and Seismic'!K26*0.6 -> 0 | N4: =N3+M4 -> 16.003543 | O4: ='Wind and Seismic'!K16 -> 132.07 | P4: ='Wind and Seismic'!K27 -> 0 | Q4: =P4-O4 -> -132.07 | R4: =M4*(Q4) -> 0 | S4: =R4+M3*(P3-O4) -> 387.92588 | T4: =0.6*('Wind and Seismic'!$Q$15) -> 8.3278759 | U4: ='Wind and Seismic'!K30 -> 0 | V4: ='Wind and Seismic'!K21 -> 132.07 | W4: 132.07 | X4: =IF(B4=0,0,0.6*('Wind and Seismic'!$Q$13*(U3*(V3-W4)+U4*(V4-W4)))) -> 0
A5: 8 | B5: =('Wind and Seismic'!H19)*12 -> 108 | C5: ='Wind and Seismic'!H15 -> 0.56253 | D5: =PI()/4*(B5^2-(B5-C5*2)^2) -> 189.86781 | E5: =PI()/64*(B5^4-(B5-C5*2)^4) -> 273958.51 | F5: =IF(B5=0,0,E5/(B5/2)) -> 5073.3058 | G5: =G4 -> 0 | H5: =H4 -> 0 | I5: ='Wind and Seismic'!H30 -> 25.843118 | J5: =J4+G5 -> 2122 | K5: =K4+H5 -> 0 | L5: =L4+I5 -> 133.52882 | M5: ='Wind and Seismic'!H26*0.6 -> 3.9956094 | N5: =N4+M5 -> 19.999152 | O5: ='Wind and Seismic'!H16 -> 92.07 | P5: ='Wind and Seismic'!H27 -> 112.32306 | Q5: =P5-O5 -> 20.253059 | R5: =M5*(Q5) -> 80.923314 | S5: =R5+M3*(P3-O5)+M4*(P4-O5) -> 1108.9909 | T5: =0.6*('Wind and Seismic'!$Q$15) -> 8.3278759 | U5: ='Wind and Seismic'!H30 -> 25.843118 | V5: ='Wind and Seismic'!H21 -> 112.07 | W5: 92.07 | X5: =0.6*('Wind and Seismic'!$Q$13*(U3*(V3-W5)+U4*(V4-W5)+U5*(V5-W5))) -> 512.33167
A6: 7 | B6: =('Wind and Seismic'!E19)*12 -> 108 | C6: ='Wind and Seismic'!E15 -> 0.625 | D6: =PI()/4*(B6^2-(B6-C6*2)^2) -> 210.83032 | E6: =PI()/64*(B6^4-(B6-C6*2)^4) -> 303853.43 | F6: =IF(B6=0,0,E6/(B6/2)) -> 5626.9154 | G6: =G5 -> 0 | H6: =H5 -> 0 | I6: ='Wind and Seismic'!E30 -> 28.696349 | J6: =J5+G6 -> 2122 | K6: =K5+H6 -> 0 | L6: =L5+I6 -> 162.22517 | M6: ='Wind and Seismic'!E26*0.6 -> 3.888 | N6: =N5+M6 -> 23.887152 | O6: ='Wind and Seismic'!E16 -> 52.07 | P6: ='Wind and Seismic'!E27 -> 72.469493 | Q6: =P6-O6 -> 20.399493 | R6: =M6*(Q6) -> 79.313228 | S6: =R6+M3*(P3-O6)+M4*(P4-O6)+M5*(P5-O6) -> 1988.2702 | T6: =0.6*('Wind and Seismic'!$Q$15) -> 8.3278759 | U6: ='Wind and Seismic'!E30 -> 28.696349 | V6: ='Wind and Seismic'!E21 -> 72.07 | W6: 52.07 | X6: =0.6*('Wind and Seismic'!$Q$13*(U3*(V3-W6)+U4*(V4-W6)+U5*(V5-W6)+U6*(V6-W6))) -> 835.92533
A7: 6 | B7: =('Wind and Seismic'!B19)*12 -> 108 | C7: ='Wind and Seismic'!B15 -> 0.6875 | D7: =PI()/4*(B7^2-(B7-C7*2)^2) -> 231.77836 | E7: =PI()/64*(B7^4-(B7-C7*2)^4) -> 333657.85 | F7: =IF(B7=0,0,E7/(B7/2)) -> 6178.8491 | G7: =G6 -> 0 | H7: =H6 -> 0 | I7: ='Wind and Seismic'!B30 -> 21.349845 | J7: =J6+G7 -> 2122 | K7: =K6+H7 -> 0 | L7: =L6+I7 -> 183.57501 | M7: ='Wind and Seismic'!B26*0.6 -> 2.631204 | N7: =N6+M7 -> 26.518356 | O7: ='Wind and Seismic'!B16 -> 25 | P7: ='Wind and Seismic'!B27 -> 38.882758 | Q7: =P7-O7 -> 13.882758 | R7: =M7*(Q7) -> 36.528369 | S7: =R7+M3*(P3-O7)+M4*(P4-O7)+M5*(P5-O7)+M6*(P6-O7) -> 2671.4238 | T7: =0.6*('Wind and Seismic'!$Q$15) -> 8.3278759 | U7: ='Wind and Seismic'!B30 -> 21.349845 | V7: ='Wind and Seismic'!B21 -> 38.535 | W7: 25 | X7: =0.6*('Wind and Seismic'!$Q$13*(U3*(V3-W7)+U4*(V4-W7)+U5*(V5-W7)+U6*(V6-W7)+U7*(V7-W7))) -> 1057.3315
A8: 5 | B8: ='Wind and Seismic'!N37*12 -> 0 | C8: ='Wind and Seismic'!N33 -> 0 | D8: =PI()/4*(B8^2-(B8-C8*2)^2) -> 0 | E8: =PI()/64*(B8^4-(B8-C8*2)^4) -> 0 | F8: =IF(B8=0,0,E8/(B8/2)) -> 0 | G8: =G7 -> 0 | H8: =H7 -> 0 | I8: ='Wind and Seismic'!N56 -> 0 | J8: =J7+G8 -> 2122 | K8: =K7+H8 -> 0 | L8: =L7+I8 -> 183.57501 | M8: ='Wind and Seismic'!N51*0.6 -> 0 | N8: =N7+M8 -> 26.518356 | O8: ='Wind and Seismic'!N34 -> 0 | P8: ='Wind and Seismic'!N52 -> 0 | Q8: =P8-O8 -> 0 | R8: =M8*(Q8) -> 0 | S8: =R8+M3*(P3-O8)+M4*(P4-O8)+M5*(P5-O8)+M6*(P6-O8)+M7*(P7-O8) -> 3334.3827 | W8: 0
A9: 4 | B9: ='Wind and Seismic'!K37*12 -> 138.72 | C9: ='Wind and Seismic'!K33 -> 0.75 | D9: =PI()/4*(B9^2-(B9-C9*2)^2) -> 325.08415 | E9: =PI()/64*(B9^4-(B9-C9*2)^4) -> 773549.26 | F9: =IF(B9=0,0,E9/(B9/2)) -> 11152.671 | G9: =G8 -> 0 | H9: =H8 -> 0 | I9: ='Wind and Seismic'!K56 -> 3.9396 | J9: =J8+G9 -> 2122 | K9: =K8+H9 -> 0 | L9: =L8+I9 -> 187.51461 | M9: ='Wind and Seismic'!K51*0.6 -> 0.444096 | N9: =N8+M9 -> 26.962452 | O9: ='Wind and Seismic'!K34 -> 21 | P9: ='Wind and Seismic'!K52 -> 23 | Q9: =P9-O9 -> 2 | R9: =M9*(Q9) -> 0.888192 | S9: =R9+M3*(P3-O9)+M4*(P4-O9)+M5*(P5-O9)+M6*(P6-O9)+M7*(P7-O9)+M8*(P8-O9) -> 2778.3854 | T9: =0.6*('Wind and Seismic'!$Q$15) -> 8.3278759 | U9: ='Wind and Seismic'!K56 -> 3.9396 | V9: ='Wind and Seismic'!K46 -> 22.834835 | W9: 21 | X9: =0.6*('Wind and Seismic'!$Q$13*(U3*(V3-W9)+U4*(V4-W9)+U5*(V5-W9)+U6*(V6-W9)+U7*(V7-W9)+U9*(V9-W9))) -> 1090.2256
A10: 3 | B10: =('Wind and Seismic'!H37)*12 -> 192.48 | C10: ='Wind and Seismic'!H33 -> 0.625 | D10: =PI()/4*(B10^2-(B10-C10*2)^2) -> 376.70641 | E10: =PI()/64*(B10^4-(B10-C10*2)^4) -> 1733260.7 | F10: =IF(B10=0,0,E10/(B10/2)) -> 18009.774 | G10: =G9 -> 0 | H10: =H9 -> 0 | I10: ='Wind and Seismic'!H56 -> 7.7371 | J10: =J9+G10 -> 2122 | K10: =K9+H10 -> 0 | L10: =L9+I10 -> 195.25171 | M10: ='Wind and Seismic'!H51*0.6 -> 1.04328 | N10: =N9+M10 -> 28.005732 | O10: ='Wind and Seismic'!H34 -> 14 | P10: ='Wind and Seismic'!H52 -> 17.541304 | Q10: =P10-O10 -> 3.5413039 | R10: =M10*(Q10) -> 3.6945715 | S10: =R10+M3*(P3-O10)+M4*(P4-O10)+M5*(P5-O10)+M6*(P6-O10)+M7*(P7-O10)+M8*(P8-O10)+M9*(P9-O10) -> 2970.8172 | T10: =0.6*('Wind and Seismic'!$Q$15) -> 8.3278759 | U10: ='Wind and Seismic'!H56 -> 7.7371 | V10: ='Wind and Seismic'!H46 -> 17.124553 | W10: 14 | X10: =0.6*('Wind and Seismic'!$Q$13*(U3*(V3-W10)+U4*(V4-W10)+U5*(V5-W10)+U6*(V6-W10)+U7*(V7-W10)+U9*(V9-W10)+U10*(V10-W10))) -> 1147.9295
A11: 2 | B11: =('Wind and Seismic'!E37)*12 -> 246.24 | C11: ='Wind and Seismic'!E33 -> 0.5625 | D11: =PI()/4*(B11^2-(B11-C11*2)^2) -> 434.14798 | E11: =PI()/64*(B11^4-(B11-C11*2)^4) -> 3275524.4 | F11: =IF(B11=0,0,E11/(B11/2)) -> 26604.324 | G11: =G10 -> 0 | H11: =H10 -> 0 | I11: ='Wind and Seismic'!E56 -> 9.2267 | J11: =J10+G11 -> 2122 | K11: =K10+H11 -> 0 | L11: =L10+I11 -> 204.47841 | M11: ='Wind and Seismic'!E51*0.6 -> 1.381968 | N11: =N10+M11 -> 29.3877 | O11: ='Wind and Seismic'!E34 -> 7 | P11: ='Wind and Seismic'!E52 -> 10.5 | Q11: =P11-O11 -> 3.5 | R11: =M11*(Q11) -> 4.836888 | S11: =R11+M3*(P3-O11)+M4*(P4-O11)+M5*(P5-O11)+M6*(P6-O11)+M7*(P7-O11)+M8*(P8-O11)+M9*(P9-O11)+M10*(P10-O11) -> 3171.6942 | T11: =0.6*('Wind and Seismic'!$Q$15) -> 8.3278759 | U11: ='Wind and Seismic'!E56 -> 9.2267 | V11: ='Wind and Seismic'!E46 -> 10.215501 | W11: 7 | X11: =0.6*('Wind and Seismic'!$Q$13*(U3*(V3-W11)+U4*(V4-W11)+U5*(V5-W11)+U6*(V6-W11)+U7*(V7-W11)+U9*(V9-W11)+U10*(V10-W11)+U11*(V11-W11))) -> 1205.846
A12: 1 | B12: =('Wind and Seismic'!B37)*12 -> 300 | C12: ='Wind and Seismic'!B33 -> 0.5 | D12: =PI()/4*(B12^2-(B12-C12*2)^2) -> 470.4535 | E12: =PI()/64*(B12^4-(B12-C12*2)^4) -> 5274989.3 | F12: =IF(B12=0,0,E12/(B12/2)) -> 35166.595 | G12: =G11 -> 0 | H12: =H11 -> 0 | I12: ='Wind and Seismic'!B56 -> 10.1871 | J12: =J11+G12 -> 2122 | K12: =K11+H12 -> 0 | L12: =L11+I12 -> 214.66551 | M12: ='Wind and Seismic'!B51*0.6 -> 1.720656 | N12: =N11+M12 -> 31.108356 | O12: ='Wind and Seismic'!B34 -> 0 | P12: ='Wind and Seismic'!B52 -> 3.5 | Q12: =P12-O12 -> 3.5 | R12: =M12*(Q12) -> 6.022296 | S12: =R12+M3*(P3-O12)+M4*(P4-O12)+M5*(P5-O12)+M6*(P6-O12)+M7*(P7-O12)+M8*(P8-O12)+M9*(P9-O12)+M10*(P10-O12)+M11*(P11-O12) -> 3383.4304 | T12: =0.6*('Wind and Seismic'!$Q$15) -> 8.3278759 | U12: ='Wind and Seismic'!B56 -> 10.1871 | V12: ='Wind and Seismic'!B46 -> 3.2710964 | W12: 0 | X12: =0.6*('Wind and Seismic'!$Q$13*(U3*(V3-W12)+U4*(V4-W12)+U5*(V5-W12)+U6*(V6-W12)+U7*(V7-W12)+U10*(V10-W12)+U11*(V11-W12)+U12*(V12-W12))) -> 1263.6851
A14: Allowable compressive stress for column
A15: FY | B15: 36000 | C15: psi
A16: k | B16: 2
A18: (R/t)c | B18: =VLOOKUP(B15,P21:Q27,2,FALSE) -> 334
A19: E | B19: 29000000 | C19: psi
A20: Segement | B20: Radius(in) | C20: Thickness(in) | D20: R/t | E20: A (in2) | F20: I (in4) | G20: r(in) | H20: C0 | I20: FL (ksi) | J20: KL/r | K20: C'c | L20: kf | M20: Fa (ksi) | N20: Fb (ksi) | P20: Fy | Q20: (R/t)c
A21: {=A3:A12} -> Tank | B21: - | C21: - | D21: - | E21: - | F21: - | G21: - | H21: - | I21: - | J21: - | K21: - | L21: - | M21: - | N21: {=I21:I30} -> - | P21: 30000 | Q21: 403
A22: 9 | B22: {=B4:B12/2} -> 0 | C22: {=C4:C12} -> 0 | D22: =IF(B22=0,0,B22/C22) -> 0 | E22: {=D4:D12} -> 0 | F22: {=E4:E12} -> 0 | G22: =IF(B22=0,0,SQRT(F22/E22)) -> 0 | H22: =IF(B22=0,0,MAX(0.125,1022/(195+D22))) -> 0 | I22: =IF(B22=0,0,IF(D22<$B$18,MIN(233*$B$15/(2*(166+D22)),$B$15/2),H22*$B$19/2/D22)/1000) -> 0 | J22: =IF(B22=0,0,$B$16*12*('Wind and Seismic'!B35+'Wind and Seismic'!E35+'Wind and Seismic'!H35+'Wind and Seismic'!K35+'Wind and Seismic'!N35+'Wind and Seismic'!B17+'Wind and Seismic'!E17+'Wind and Seismic'!H17+'Wind and Seismic'!K17)/((G22+G23+G24+G25+G26+G27+G28+G29+G30)/9)) -> 0 | K22: =IF(B22=0,0,SQRT(PI()^2*$B$19/I22/1000)) -> 0 | L22: =IF(B22=0,0,IF(J22>K22,0.5*(K22/J22)^2,IF(J22<25,1,1-0.5*(J22/K22)^2))) -> 0 | M22: =IF(B22=0,0,L22*I22) -> 0 | N22: 0 | P22: 32000 | Q22: 377
A23: 8 | B23: 54 | C23: 0.56253 | D23: =IF(B23=0,0,B23/C23) -> 95.99488 | E23: 189.86781 | F23: 273958.51 | G23: =IF(B23=0,0,SQRT(F23/E23)) -> 37.985402 | H23: =IF(B23=0,0,MAX(0.125,1022/(195+D23))) -> 3.5120893 | I23: =IF(B23=0,0,IF(D23<$B$18,MIN(233*$B$15/(2*(166+D23)),$B$15/2),H23*$B$19/2/D23)/1000) -> 16.007946 | J23: =IF(B23=0,0,$B$16*12*('Wind and Seismic'!B35+'Wind and Seismic'!E35+'Wind and Seismic'!H35+'Wind and Seismic'!K35+'Wind and Seismic'!N35+'Wind and Seismic'!B17+'Wind and Seismic'!E17+'Wind and Seismic'!H17)/((G23+G24+G25+G26+G27+G28+G29+G30)/7)) -> 52.422119 | K23: =IF(B23=0,0,SQRT(PI()^2*$B$19/I23/1000)) -> 133.71529 | L23: =IF(B23=0,0,IF(J23>K23,0.5*(K23/J23)^2,IF(J23<25,1,1-0.5*(J23/K23)^2))) -> 0.92315121 | M23: =IF(B23=0,0,L23*I23) -> 14.777755 | N23: 16.007946 | P23: 34000 | Q23: 354
A24: 7 | B24: 54 | C24: 0.625 | D24: =IF(B24=0,0,B24/C24) -> 86.4 | E24: 210.83032 | F24: 303853.43 | G24: =IF(B24=0,0,SQRT(F24/E24)) -> 37.963438 | H24: =IF(B24=0,0,MAX(0.125,1022/(195+D24))) -> 3.6318408 | I24: =IF(B24=0,0,IF(D24<$B$18,MIN(233*$B$15/(2*(166+D24)),$B$15/2),H24*$B$19/2/D24)/1000) -> 16.616482 | J24: =IF(B24=0,0,$B$16*12*('Wind and Seismic'!B35+'Wind and Seismic'!E35+'Wind and Seismic'!H35+'Wind and Seismic'!K35+'Wind and Seismic'!N35+'Wind and Seismic'!B17+'Wind and Seismic'!E17)/((G24+G25+G26+G27+G28+G29+G30)/6)) -> 34.412753 | K24: =IF(B24=0,0,SQRT(PI()^2*$B$19/I24/1000)) -> 131.24396 | L24: =IF(B24=0,0,IF(J24>K24,0.5*(K24/J24)^2,IF(J24<25,1,1-0.5*(J24/K24)^2))) -> 0.96562441 | M24: =IF(B24=0,0,L24*I24) -> 16.04528 | N24: 16.616482 | P24: 36000 | Q24: 334
A25: 6 | B25: 54 | C25: 0.6875 | D25: =IF(B25=0,0,B25/C25) -> 78.545455 | E25: 231.77836 | F25: 333657.85 | G25: =IF(B25=0,0,SQRT(F25/E25)) -> 37.941477 | H25: =IF(B25=0,0,MAX(0.125,1022/(195+D25))) -> 3.736125 | I25: =IF(B25=0,0,IF(D25<$B$18,MIN(233*$B$15/(2*(166+D25)),$B$15/2),H25*$B$19/2/D25)/1000) -> 17.150186 | J25: =IF(B25=0,0,$B$16*12*('Wind and Seismic'!B35+'Wind and Seismic'!E35+'Wind and Seismic'!H35+'Wind and Seismic'!K35+'Wind and Seismic'!N35+'Wind and Seismic'!B17)/((G25+G26+G27+G28+G29+G30)/5)) -> 17.991205 | K25: =IF(B25=0,0,SQRT(PI()^2*$B$19/I25/1000)) -> 129.1857 | L25: =IF(B25=0,0,IF(J25>K25,0.5*(K25/J25)^2,IF(J25<25,1,1-0.5*(J25/K25)^2))) -> 1 | M25: =IF(B25=0,0,L25*I25) -> 17.150186 | N25: 17.150186 | P25: 38000 | Q25: 316
A26: 5 | B26: 0 | C26: 0 | D26: =IF(B26=0,0,B26/C26) -> 0 | E26: 0 | F26: 0 | G26: =IF(B26=0,0,SQRT(F26/E26)) -> 0 | H26: =IF(B26=0,0,MAX(0.125,1022/(195+D26))) -> 0 | I26: =IF(B26=0,0,IF(D26<$B$18,MIN(233*$B$15/(2*(166+D26)),$B$15/2),H26*$B$19/2/D26)/1000) -> 0 | J26: =IF(B26=0,0,$B$16*12*('Wind and Seismic'!B35+'Wind and Seismic'!E35+'Wind and Seismic'!H35+'Wind and Seismic'!K35+'Wind and Seismic'!N35)/((G26+G27+G28+G29+G30)/5)) -> 0 | K26: =IF(B26=0,0,SQRT(PI()^2*$B$19/I26/1000)) -> 0 | L26: =IF(B26=0,0,IF(J26>K26,0.5*(K26/J26)^2,IF(J26<25,1,1-0.5*(J26/K26)^2))) -> 0 | M26: =IF(B26=0,0,L26*I26) -> 0 | N26: 0 | P26: 40000 | Q26: 299
A27: 4 | B27: 69.36 | C27: 0.75 | D27: =IF(B27=0,0,B27/C27) -> 92.48 | E27: 325.08415 | F27: 773549.26 | G27: =IF(B27=0,0,SQRT(F27/E27)) -> 48.780482 | H27: =IF(B27=0,0,MAX(0.125,1022/(195+D27))) -> 3.5550299 | I27: =IF(B27=0,0,IF(D27<$B$18,MIN(233*$B$15/(2*(166+D27)),$B$15/2),H27*$B$19/2/D27)/1000) -> 16.225627 | J27: =IF(B27=0,0,$B$16*12*('Wind and Seismic'!B35+'Wind and Seismic'!E35+'Wind and Seismic'!H35+'Wind and Seismic'!K35)/((G27+G28+G29+G30)/4)) -> 7.7579129 | K27: =IF(B27=0,0,SQRT(PI()^2*$B$19/I27/1000)) -> 132.81531 | L27: =IF(B27=0,0,IF(J27>K27,0.5*(K27/J27)^2,IF(J27<25,1,1-0.5*(J27/K27)^2))) -> 1 | M27: =IF(B27=0,0,L27*I27) -> 16.225627 | N27: 16.225627
A28: 3 | B28: 96.24 | C28: 0.625 | D28: =IF(B28=0,0,B28/C28) -> 153.984 | E28: 376.70641 | F28: 1733260.7 | G28: =IF(B28=0,0,SQRT(F28/E28)) -> 67.831346 | H28: =IF(B28=0,0,MAX(0.125,1022/(195+D28))) -> 2.928501 | I28: =IF(B28=0,0,IF(D28<$B$18,MIN(233*$B$15/(2*(166+D28)),$B$15/2),H28*$B$19/2/D28)/1000) -> 13.106905 | J28: =IF(B28=0,0,$B$16*12*('Wind and Seismic'!B35+'Wind and Seismic'!E35+'Wind and Seismic'!H35)/((G28+G29+G30)/3)) -> 5.8024168 | K28: =IF(B28=0,0,SQRT(PI()^2*$B$19/I28/1000)) -> 147.77426 | L28: =IF(B28=0,0,IF(J28>K28,0.5*(K28/J28)^2,IF(J28<25,1,1-0.5*(J28/K28)^2))) -> 1 | M28: =IF(B28=0,0,L28*I28) -> 13.106905 | N28: 13.106905
A29: 2 | B29: 123.12 | C29: 0.5625 | D29: =IF(B29=0,0,B29/C29) -> 218.88 | E29: 434.14798 | F29: 3275524.4 | G29: =IF(B29=0,0,SQRT(F29/E29)) -> 86.860341 | H29: =IF(B29=0,0,MAX(0.125,1022/(195+D29))) -> 2.4693148 | I29: =IF(B29=0,0,IF(D29<$B$18,MIN(233*$B$15/(2*(166+D29)),$B$15/2),H29*$B$19/2/D29)/1000) -> 10.896903 | J29: =IF(B29=0,0,$B$16*12*('Wind and Seismic'!E35+'Wind and Seismic'!B35)/((G29+G30)/2)) -> 3.4863862 | K29: =IF(B29=0,0,SQRT(PI()^2*$B$19/I29/1000)) -> 162.06802 | L29: =IF(B29=0,0,IF(J29>K29,0.5*(K29/J29)^2,IF(J29<25,1,1-0.5*(J29/K29)^2))) -> 1 | M29: =IF(B29=0,0,L29*I29) -> 10.896903 | N29: 10.896903
A30: 1 | B30: 150 | C30: 0.5 | D30: =IF(B30=0,0,B30/C30) -> 300 | E30: 470.4535 | F30: 5274989.3 | G30: =IF(B30=0,0,SQRT(F30/E30)) -> 105.88939 | H30: =IF(B30=0,0,MAX(0.125,1022/(195+D30))) -> 2.0646465 | I30: =IF(B30=0,0,IF(D30<$B$18,MIN(233*$B$15/(2*(166+D30)),$B$15/2),H30*$B$19/(2*D30))/1000) -> 9 | J30: =IF(B30=0,0,$B$16*12*'Wind and Seismic'!B35/G30) -> 1.5865613 | K30: =IF(B30=0,0,SQRT(PI()^2*$B$19/I30/1000)) -> 178.33132 | L30: =IF(B30=0,0,IF(J30>K30,0.5*(K30/J30)^2,IF(J30<25,1,1-0.5*(J30/K30)^2))) -> 1 | M30: =IF(B30=0,0,L30*I30) -> 9 | N30: 9
A32: {=A20:A30} -> Segement | B32: fa | C32: fb | D32: check
A33: Tank | B33: - | C33: - | D33: -
A34: 9 | B34: =IF(D4=0,0,(J4+K4+L4)/D4) -> 0 | C34: =IF(F4=0,0,S4*12/F4) -> 0 | D34: =IF(B34+C34=0,"NA",B34/M22+C34/N22) -> NA
A35: 8 | B35: =IF(D5=0,0,(J5+K5+L5)/D5) -> 11.879469 | C35: =IF(F5=0,0,S5*12/F5) -> 2.6231202 | D35: =IF(B35+C35=0,"NA",B35/M23+C35/N23) -> 0.96773874
A36: 7 | B36: =IF(D6=0,0,(J6+K6+L6)/D6) -> 10.834424 | C36: =IF(F6=0,0,S6*12/F6) -> 4.2401993 | D36: =IF(B36+C36=0,"NA",B36/M24+C36/N24) -> 0.93042091
A37: 6 | B37: =IF(D7=0,0,(J7+K7+L7)/D7) -> 9.9473264 | C37: =IF(F7=0,0,S7*12/F7) -> 5.1881969 | D37: =IF(B37+C37=0,"NA",B37/M25+C37/N25) -> 0.88252824
A38: 5 | B38: =IF(D8=0,0,(J8+K8+L8)/D8) -> 0 | C38: =IF(F8=0,0,S8*12/F8) -> 0 | D38: =IF(B38+C38=0,"NA",B38/M26+C38/N26) -> NA
A39: 4 | B39: =IF(D9=0,0,(J9+K9+L9)/D9) -> 7.1043592 | C39: =IF(F9=0,0,S9*12/F9) -> 2.9894745 | D39: =IF(B39+C39=0,"NA",B39/M27+C39/N27) -> 0.62209207
A40: 3 | B40: =IF(D10=0,0,(J10+K10+L10)/D10) -> 6.1513466 | C40: =IF(F10=0,0,S10*12/F10) -> 1.9794699 | D40: =IF(B40+C40=0,"NA",B40/M28+C40/N28) -> 0.62034602
A41: 2 | B41: =IF(D11=0,0,(J11+K11+L11)/D11) -> 5.3587222 | C41: =IF(F11=0,0,S11*12/F11) -> 1.4306069 | D41: =IF(B41+C41=0,"NA",B41/M29+C41/N29) -> 0.62305126
A42: 1 | B42: =IF(D12=0,0,(J12+K12+L12)/D12) -> 4.9668363 | C42: =IF(F12=0,0,S12*12/F12) -> 1.1545378 | D42: =IF(B42+C42=0,"NA",B42/M30+C42/N30) -> 0.68015268

Sheet Tanks Information
A1: Volumn (Gal.) | B1: Diameter (ft) | C1: Centroied (ft) | D1: Tank Height (ft) | E1: Weight of Water (Kips) | F1: Weight of Steel (Kips) | G1: Total Weight (Kips) | H1: Projected Area (ft2)
A2: 50000 | B2: 24 | C2: 14.91 | D2: 27.5416 | E2: 448 | F2: 41.4527 | G2: =E2+F2 -> 489.4527 | H2: 478.77
A3: 75000 | B3: 27 | C3: 16.88 | D3: 31.1629 | E3: 641 | F3: 48.1182 | G3: =E3+F3 -> 689.1182 | H3: 609.33
A4: 100000 | B4: 30 | C4: 18.77 | D4: 34.7842 | E4: 883 | F4: 54.6153 | G4: =E4+F4 -> 937.6153 | H4: 755.11
A5: 125000 | B5: 32.33 | C5: 20.18 | D5: 37.1004 | E5: 1107 | F5: 65.685 | G5: =E5+F5 -> 1172.685 | H5: 874.96
A6: 150000 | B6: 34 | C6: 21.27 | D6: 39.1126 | E6: 1283 | F6: 81.2382 | G6: =E6+F6 -> 1364.2382 | H6: 966.01
A7: 200000 | B7: 40.5 | C7: 22.56 | D7: 41.2088 | E7: 1969 | F7: 90.7952 | G7: =E7+F7 -> 2059.7952 | H7: 1163
A8: 250000 | B8: 43.67 | C8: 24.24 | D8: 43.9459 | E8: 2122 | F8: 107.6857 | G8: =E8+F8 -> 2229.6857 | H8: 1347.18
A9: 300000 | B9: 46.5 | C9: 26.04 | D9: 46.9516 | E9: 2603 | F9: 115.0325 | G9: =E9+F9 -> 2718.0325 | H9: 1552.23
A10: 400000 | B10: 51.5 | C10: 28.83 | D10: 51.9871 | E10: 3455 | F10: 154.713 | G10: =E10+F10 -> 3609.713 | H10: 1900.48
A11: 500000 | B11: 54 | C11: 30.96 | D11: 54.2548 | E11: 4305 | F11: 174.2953 | G11: =E11+F11 -> 4479.2953 | H11: 2111.58
A12: 600000 | B12: 62.5 | D12: 57.2651 | E12: 5474 | F12: 221.4761 | G12: =E12+F12 -> 5695.4761
A13: 750000 | B13: 83 | C13: 35.12 | D13: 62.1187 | E13: 6798 | F13: 268.2621 | G13: =E13+F13 -> 7066.2621 | H13: 2828.77
A14: 1000000
