Workbook

Sheet ACI 318-19 
A1: ACI 318-19 — Formulas Used in This Workbook (Chapters 19–22) | F1: Table 19.2.4.1(a)—Values of landa for lightweight concrete based on equilibrium density | L1: Table 19.2.4.1(b)—Values of 􀈜 for lightweight concrete based on composition of aggregates
A3: Check / Term | B3: ACI 318-19 Ref. | C3: Formula (as implemented) | D3: Notes / Units
A4: Concrete lightweight factor, λ | B4: 19.2.4.1 / Table 19.2.4.1(a) | C4: λ = 1.0 (wc>135 pcf); λ = 0.75 (wc≤100 pcf); else λ = min(1.0, 0.0075·wc) | D4: wc = equilibrium density (pcf)
A5: Steel modulus, Es | B5: 20.2.2.2 | C5: Es = 29,000,000 psi | D5: Nonprestressed bars & wires
A6: Yield strain, εty | B6: 21.2.2.1 | C6: εty = fy/Es | D6: Grade 60 permitted εty=0.002
A7: Strength reduction factor (shear) | B7: Table 21.2.1 | C7: ϕv = 0.75 | D7: Used for one-way & punching shear
A8: Strength reduction factor (bearing) | B8: Table 21.2.1 | C8: ϕb = 0.65 | D8: Used for concrete bearing
A9: Strength reduction factor (flexure) | B9: Table 21.2.2 | C9: For ‘Other’: ϕ=0.65 if εt≤εty; ϕ=0.90 if εt≥εty+0.003; else ϕ=0.65+0.25·(εt−εty)/0.003 | D9: Workbook computes εt at nominal strength
A10: Concrete max compressive strain | B10: 22.2.2.1 | C10: εcu = 0.003 | D10: Used in εt calculation
A11: Stress block depth | B11: 22.2.2.4.1 | C11: a = β1·c | D11: Equivalent rectangular stress block
A12: β1 factor | B12: Table 22.2.2.4.3 | C12: β1 = 0.85 (fc'≤4000 psi); else β1 = max(0.65, 0.85 − 0.05·(fc'−4000)/1000) | D12: Inch-pound units
A13: Compression block force | B13: 22.2.2.4.1 | C13: C = 0.85·fc'·a·b | D13: Used implicitly through a-expression
A14: Flexural nominal strength (singly reinforced) | B14: 22.2 assumptions + equilibrium | C14: Mn = As·fy·(d − a/2) | D14: Assumes steel yields; check via εt
... A20: Nominal bearing strength | B20: Table 22.8.3.2 | C20: If support wider on all sides: Bn = min(0.85·fc'·A1·√(A2/A1), 2·0.85·fc'·A1); otherwise Bn=0.85·fc'·A1 | D20: A2 from 1V:2H frustum within support

Sheet Wind and Seismic
A1: wind load paramets | M1: seismic base shear
A2: kzt | B2: 1 | M2: Ss | N2: 0.346 | O2: g
A3: kd | B3: 1 | M3: S1 | N3: 0.15 | O3: g
A4: I | B4: 1 | M4: SDS | N4: =2/3*1.6*N2 -> 0.36906667 | O4: g
A5: V | B5: 116 | C5: mph | D5: Number of Columns | E5: 4 | M5: SD1 | N5: =2/3*2.4*N3 -> 0.24 | O5: g
A6: exposure | B6: D | M6: Ri | N6: 3
A7: α | B7: =IF(B6="C",9.5,11.5) -> 11.5 | M7: IE | N7: 1.5
A8: Zg | B8: =IF(B6="C",900,700) -> 700 | C8: ft | M8: TL | N8: 12 | O8: sec
A9: G | B9: 1 | M9: Ti | N9: 1.5511 | O9: sec
A10: Cf | B10: 0.7 | M10: Ts | N10: =N5/N4 -> 0.65028902 | O10: sec
A11: λ | B11: 0.6 | M11: Sai | N11: =IF(N9<N10,N4,IF(N9>N8,N5*N8/N9^2,N5/N9)) -> 0.1547289
A12: λ(0.00256 Kzt Kd I V2) | B12: =B11*0.00256*B2*B3*B4*B5^2 -> 20.668416 | C12: psf | M12: λ | N12: 0.7
A13: column | D13: column | G13: column | J13: column | M13: Ai | N13: =MAX(N12*N11*N7/N6,0.36*N3*N7/N6) -> 0.054155116 | O13: ft/s2
A14: Bay Number | B14: 1 | D14: Bay Number | E14: 2 | G14: Bay Number | H14: 3 | J14: Bay Number | K14: 4 | M14: COM | N14: =(B29+E29+H29+K29+B47+E47+H47+K47+(B60*B64))/B70 -> 108.46647
A15: Thickness | B15: 0.3125 | C15: in | D15: Thickness | E15: 0.3125 | F15: in | G15: Thickness | H15: 0.25 | I15: in | J15: Thickness | K15: 0 | L15: in | M15: V | N15: =N13*B70 -> 52.295444 | O15: kips
A16: hi | B16: 0 | C16: ft | D16: hi | E16: =B18 -> 38.0544 | G16: hi | H16: =E18 -> 73.1674 | I16: ft | J16: hi | K16: 0 | L16: ft | M16: Seismic base moment | N16: =N15*N14 -> 5672.3022 | O16: kips-ft
A17: Height of the cylinder | B17: 38.0544 | C17: ft | D17: Height of the cylinder | E17: 35.113 | F17: ft | G17: Height of the cylinder | H17: 35.1488 | I17: ft | J17: Height of the cylinder | K17: 0 | L17: ft
A18: hf | B18: =B16+B17 -> 38.0544 | C18: ft | D18: hf | E18: =E16+E17 -> 73.1674 | G18: hf | H18: =H16+H17 -> 108.3162 | I18: ft | J18: hf | K18: =K16+K17 -> 0 | L18: ft
A19: Diameter of the cylinder | B19: 1.67 | C19: ft | D19: Diameter of the cylinder | E19: 1.67 | F19: ft | G19: Diameter of the cylinder | H19: 1.67 | I19: ft | J19: Diameter of the cylinder | K19: 0 | L19: ft
A20: Awind | B20: =IF(B15=0,0,$E$5*B19*B17) -> 254.20339 | C20: ft2 | D20: Awind | E20: =IF(E15=0,0,$E$5*E19*E17) -> 234.55484 | F20: ft2 | G20: Awind | H20: =IF(H15=0,0,$E$5*H19*H17) -> 234.79398 | I20: ft2 | J20: Awind | K20: =IF(K15=0,0,$E$5*K19*K17) -> 0 | L20: ft2
A21: Centroid | B21: =B16+B17/2 -> 19.0272 | C21: ft | D21: Centroid | E21: =E16+E17/2 -> 55.6109 | F21: ft | G21: Centroid | H21: =H16+H17/2 -> 90.7418 | I21: ft | J21: Centroid | K21: =K16+K17/2 -> 0 | L21: ft
A22: kzi | B22: =2.01*(MAX(B16,15)/$B$8)^(2/$B$7) -> 1.0302296 | D22: kzi | E22: =2.01*(MAX(E16,15)/$B$8)^(2/$B$7) -> 1.2112936 | G22: kzi | H22: =2.01*(MAX(H16,15)/$B$8)^(2/$B$7) -> 1.3571428 | J22: kzi | K22: =2.01*(MAX(K16,15)/$B$8)^(2/$B$7) -> 1.0302296
A23: kzf | B23: =2.01*(MAX(B18,15)/$B$8)^(2/$B$7) -> 1.2112936 | D23: kzf | E23: =2.01*(MAX(E18,15)/$B$8)^(2/$B$7) -> 1.3571428 | G23: kzf | H23: =2.01*(MAX(H18,15)/$B$8)^(2/$B$7) -> 1.4529682 | J23: kzf | K23: =2.01*(MAX(K18,15)/$B$8)^(2/$B$7) -> 1.0302296
A24: qzi | B24: =B12*B22 -> 21.293213 | C24: psf | D24: qzi | E24: =B12*E22 -> 25.03552 | F24: psf | G24: qzi | H24: =B12*H22 -> 28.049992 | I24: psf | J24: qzi | K24: =MAX(K22*$B$12,30*$B$10) -> 21.293213 | L24: psf
A25: qzf | B25: =B12*B23 -> 25.03552 | C25: psf | D25: qzf | E25: =B12*E23 -> 28.049992 | F25: psf | G25: qzf | H25: =B12*H23 -> 30.030552 | I25: psf | J25: qzf | K25: =MAX(K23*$B$12,30*$B$10) -> 21.293213 | L25: psf
A26: F | B26: =MAX(30*B10*B20/1000,B9*B10*(B24+B25)/2*B20/1000) -> 5.3382712 | C26: kips | D26: F | E26: =MAX(30*B10*E20/1000,B9*B10*(E24+E25)/2*E20/1000) -> 4.9256516 | F26: kips | G26: F | H26: =MAX(30*B10*H20/1000,B9*B10*(H24+H25)/2*H20/1000) -> 4.9306737 | I26: kips | J26: F | K26: =(K24+K25)/2*K20/1000 -> 0 | L26: kips | M26: Wind base shear | N26: =K26+H26+E26+B26 -> 15.194597 | O26: kips
A27: F location | B27: =B16+((B24*B17^2/2+2/3*0.5*B17^2*(B25-B24))/(B24*B17+0.5*B17*(B25-B24))) -> 19.539521 | C27: ft | D27: F location | E27: =E16+((E24*E17^2/2+2/3*0.5*E17^2*(E25-E24))/(E24*E17+0.5*E17*(E25-E24))) -> 55.943217 | F27: ft | G27: F location | H27: =H16+((H24*H17^2/2+2/3*0.5*H17^2*(H25-H24))/(H24*H17+0.5*H17*(H25-H24))) -> 90.941564 | I27: ft | J27: F location | K27: 0 | L27: ft
A28: Wind moment At base | B28: =B27*B26 -> 104.30727 | C28: kips | D28: Wind moment At base | E28: =E27*E26 -> 275.5568 | F28: kips | G28: Wind moment At base | H28: =H27*H26 -> 448.40317 | I28: kips | J28: Wind moment At base | K28: 0 | L28: kips | M28: Wind base moment | N28: =K28+H28+E28+B28 -> 828.26723 | O28: kips-ft
A29: Center of mass x weight | B29: =B30*B21 -> 222.10396 | D29: Center of mass x weight | E29: =E30*E21 -> 685.6258 | G29: Center of mass x weight | H29: =H30*H21 -> 953.58499 | J29: Center of mass x weight | K29: =K30*K21 -> 0
A30: Weight | B30: =(PI()/4*(B19^2-(B19-2*B15/12)^2)*B17*490/1000*E5)+($H$54/3) -> 11.672971 | C30: kips | D30: Weight | E30: =(PI()/4*(E19^2-(E19-2*E15/12)^2)*E17*490/1000*E5)+($H$52/2+$H$54/3) -> 12.328982 | F30: kips | G30: Weight | H30: =(PI()/4*(H19^2-(H19-2*H15/12)^2)*H17*490/1000*E5)+($H$52/2+$H$54/3) -> 10.508773 | I30: kips | J30: Weight | K30: =PI()/4*(K19^2-(K19-2*K15/12)^2)*K17*490/1000*E5 -> 0 | L30: kips | M30: weight of steel | N30: =K30+H30+E30+B30 -> 34.510727 | O30: kips
A31: riser | D31: riser | G31: riser | J31: riser
A32: Bay Number | B32: 1 | D32: Bay Number | E32: 2 | G32: Bay Number | H32: 3 | J32: Bay Number | K32: 4
A33: Thickness | B33: 0.3125 | C33: in | D33: Thickness | E33: 0.3125 | F33: in | G33: Thickness | H33: 0.3125 | I33: in | J33: Thickness | K33: 0 | L33: in
A34: hi | B34: 0 | C34: ft | D34: hi | E34: =B36 -> 38.0544 | G34: hi | H34: =E36 -> 73.1674 | I34: ft | J34: hi | K34: 0 | L34: ft
A35: Height of the riser | B35: 38.0544 | C35: ft | D35: Height of the riser | E35: 35.113 | F35: ft | G35: Height of the riser | H35: 25.4993 | I35: ft | J35: Height of the riser | K35: 0 | L35: ft
A36: hf | B36: =B34+B35 -> 38.0544 | C36: ft | D36: hf | E36: =E34+E35 -> 73.1674 | G36: hf | H36: =H34+H35 -> 98.6667 | I36: ft | J36: hf | K36: =K34+K35 -> 0 | L36: ft
A37: Diameter of the riser | B37: 3 | C37: ft | D37: Diameter of the riser | E37: 3 | F37: ft | G37: Diameter of the riser | H37: 3 | I37: ft | J37: Diameter of the riser | K37: 0 | L37: ft
A38: Awind | B38: =IF(B33=0,0,B37*B35) -> 114.1632 | C38: ft2 | D38: Awind | E38: =IF(E33=0,0,E37*E35) -> 105.339 | F38: ft2 | G38: Awind | H38: =IF(H33=0,0,H37*H35) -> 76.4979 | I38: ft2 | J38: Awind | K38: =IF(K33=0,0,K37*K35) -> 0 | L38: ft2
A39: Centroid | B39: =B34+B35/2 -> 19.0272 | C39: ft | D39: Centroid | E39: =E34+E35/2 -> 55.6109 | F39: ft | G39: Centroid | H39: =H34+H35/2 -> 85.91705 | I39: ft | J39: Centroid | K39: =K34+K35/2 -> 0 | L39: ft
A40: kzi | B40: =2.01*(MAX(B34,15)/$B$8)^(2/$B$7) -> 1.0302296 | D40: kzi | E40: =2.01*(MAX(E34,15)/$B$8)^(2/$B$7) -> 1.2112936 | G40: kzi | H40: =2.01*(MAX(H34,15)/$B$8)^(2/$B$7) -> 1.3571428 | J40: kzi | K40: =2.01*(MAX(K34,15)/$B$8)^(2/$B$7) -> 1.0302296
...

Sheet Loads 
A1: Snow Load | E1: Roof Live Load | I1: Live Load | M1: Load Combination | Q1: P | S1: M
A2: Diameter of tank | B2: 32 | C2: ft | E2: Min Roof Live Load | F2: 15 | G2: psf | I2: Live Load | J2: 0 | K2: kips | M2: D | Q2: ='[1]Wind and Seismic'!B70 -> 965.66028 | S2: 0
A3: Height to consider | B3: 6.6437 | E3: Area to consider | F3: =B4 -> 667.89757 | G3: ft2 | M3: D + L | Q3: ='[1]Wind and Seismic'!B70+J2 -> 965.66028 | S3: 0
A4: Area to consider | B4: =PI()*B2*B3 -> 667.89757 | C4: ft2 | E4: Roof Live Load | F4: =F2*F3/1000 -> 10.018464 | G4: kips | M4: D + (Lr or S) | Q4: ='[1]Wind and Seismic'!B70+(MAX(B11,F4)) -> 979.1251 | S4: 0
A5: Ground snow load | B5: 25 | C5: psf | M5: D + 0.75L + 0.75(Lr or S) | Q5: ='[1]Wind and Seismic'!B70+0.75*J2+0.75*(MAX(B11,F4)) -> 975.7589 | S5: 0
A6: Exposure Factor | B6: D | M6: D + 0.6(W or E) | Q6: ='[1]Wind and Seismic'!B70 -> 965.66028 | S6: =0.6*(MAX('[1]Wind and Seismic'!B74,'[1]Wind and Seismic'!N16)) -> 3403.3813
A7: Ce | B7: =IF(B6="C",0.9,0.8) -> 0.8 | M7: D + 0.75L + 0.75(0.6W or 0.6E) + 0.75(Lr or S) | Q7: ='[1]Wind and Seismic'!B70+(0.75*J2)+(0.75*(MAX(B11,F4))) -> 975.7589 | S7: =0.45*(MAX('[1]Wind and Seismic'!B74,'[1]Wind and Seismic'!N16)) -> 2552.536
A8: Ct | B8: 1.2 | M8: 0.6D + 0.6(W or E) | Q8: =0.6*'[1]Wind and Seismic'!B70 -> 579.39617 | S8: =0.6*(MAX('[1]Wind and Seismic'!B74,'[1]Wind and Seismic'!N16)) -> 3403.3813
A9: Importance Factor | B9: RC IV
A10: Is | B10: =IF(B9="RC II",1,IF(B9="RC III",1.1,1.2)) -> 1.2
A11: Snow load | B11: =0.7*B4*B5*B7*B8*B10/1000 -> 13.464815 | C11: kips
A14: 0.6D + 0.6(W or E) | E14: D + 0.75L + 0.75(0.6W or 0.6E) + 0.75(Lr or S) | I14: D + 0.6(W or E)
A15: =Q8 -> 579.39617 | B15: kips | E15: =Q7 -> 975.7589 | F15: kips | I15: =Q6 -> 965.66028 | K15: kips
A16: =S8 -> 3403.3813 | B16: ft-kips | E16: =S7 -> 2552.536 | F16: ft-kips | I16: =S6 -> 3403.3813 | K16: ft-kips

Sheet Inputs
A1: Water Tank Foundation Design (ACI 318-19)
A3: Project / References
A4: Project | B4: Ute, IA – 100,000 gal Pedesphere
A5: Design Standard | B5: ACI 318-19 (Strength design)
A6: Units | B6: US Customary (in, ft, kip, psi)
A8: Material Properties
A9: Concrete compressive strength, f'c (psi) | F9: 4000
A10: Rebar yield strength, fy (psi) | F10: 60000
A11: Concrete unit weight (pcf) | F11: 150
A12: Steel unit weight (pcf) | F12: 490
A13: Phi factors (ACI 318-19) | F13: Shear: 0.75 (Table 21.2.1), Bearing: 0.65 (Table 21.2.1), Flexure: per Table 21.2.2
A14: Steel modulus, Es (psi) | F14: 29000000 | H14: ACI 318-19 20.2.2.2
A15: Lightweight factor, λ (auto) (19.2.4) | F15: =IF(F11>135,1,IF(F11<=100,0.75,MIN(1,0.0075*F11))) -> 1 | H15: Table 19.2.4.1(a)
A16: Geotechnical Inputs
A17: Allowable soil bearing, q_allow (psf) | F17: 4000
A18: Soil unit weight, γ_s (pcf) | F18: 120
A19: Frost depth (ft) | F19: 4
A20: Base friction coefficient μ (if needed) | F20: 0.5
A21: Soil-to-footing contact condition | F21: Uniform bearing assumed (service level)
A25: Loads (enter best-available values)
A26: Water volume (gal) | F26: 10000
A27: Water unit weight (pcf) | F27: 62.4
A28: Steel tank + appurtenances dead load, W_tank (kips) | F28: 40
A29: Concrete foundation self-weight will be computed | F29: 0
A30: Snow + roof live load (kips) | F30: ='Loads '!B11 -> 13.464815
A31: Wind overturning moment at base (kip-ft) | F31: ='Wind and Seismic'!B73 -> 34.324198
A32: Seismic base shear (kips) | F32: ='Wind and Seismic'!N14 -> 108.46647
A33: Load combinations | F33: ='Loads '!E15 -> 975.7589

Sheet Geometry
A1: Foundation Geometry
A2: Ringwall / Ring Footing Geometry (circular)
A3: Ringwall thickness (ft) | F3: 1.6666667
A4: Footing base width, B (ft) | F4: 3.0833333
A5: Radius to foundation centerline, R_cl (ft) | F5: 9
A6: Top of concrete elevation (ft) | F6: 1274.5
A7: Footing edge thickness (ft) | F7: 1.1666667
A8: Concrete cover to rebar (in) | F8: 3
A11: Derived Dimensions
A12: Inner radius to footing edge, R_in (ft) | F12: =F5 - F4/2 -> 7.4583333
A13: Outer radius to footing edge, R_out (ft) | F13: =F5 + F4/2 -> 10.541667
A14: Footing plan area, A (ft^2) | F14: =PI()*(F13^2 - F12^2) -> 174.35839
A15: Ringwall centerline radius (ft) (if needed) | F15: =F5 + (F3/2) + 0 -> 9.8333333

Sheet Bearing & Stability
A1: Soil Bearing, Uplift, and Stability Checks
A3: Service-Level Bearing Pressure
A5: Inputs
A6: Water weight, Ww (kips) | F6: =Inputs!F26/7.48052*Inputs!F27/1000 -> 83.416661
A7: Tank dead load, W(tank) (kips) | F7: =Inputs!F28 -> 40
A8: Superimposed (snow/live/wind) (kips) | F8: =IF(Inputs!F30="","",Inputs!F30) -> 13.464815 | H8: Enter as needed
A9: Footing self-weight, W_f (kips) | F9: =Geometry!F14*Geometry!F7*Inputs!F11/1000 -> 30.512719 | H9: teq = edge thickness; adjust if needed
A10: Total service vertical load, V_s (kips) | F10: =SUM(F6:F9) -> 167.39419
A11: Allowable bearing, q_allow (ksf) | F11: =Inputs!F17/1000 -> 4
A13: Results
A14: Service bearing pressure, qs = V_s/A (ksf) | F14: =F10/(Geometry!F14) -> 0.96005814
A15: Bearing utilization, qs/q_allow | F15: =F14/F11 -> 0.24001454 | H15: OK if <= 1.0

Sheet Flexure (Ring Footing)
A1: Flexural Design (per 1-ft circumferential strip)
A3: Inputs
A5: Factored moment demand, Mu (kip-in/ft) | F5: 12 | H5: Enter from analysis (soil pressure, uplift, etc.) Here I used for the normal ringwall foundition.
A6: Effective depth, d (in) | F6: =Geometry!F7*12 - Geometry!F8 -> 11 | H6: Uses edge thickness and cover
A7: Strip width, b (in) | F7: =12 -> 12
A8: Concrete strength, f'c (psi) | F8: =Inputs!F9 -> 4000
A9: Steel yield, fy (psi) | F9: =Inputs!F10 -> 60000
A10: Steel modulus, Es (psi) | F10: =Inputs!F14 -> 29000000
A11: Lightweight factor, λ | F11: =Inputs!F15 -> 1
A12: Design Calculations (per ACI 318-19 Ch.21–22)
A14: β1 (Table 22.2.2.4.3) | F14: =IF(F8<=4000,0.85,MAX(0.65,0.85-0.05*(F8-4000)/1000)) -> 0.85 | H14: Mu must be provided
A15: Yield strain, εty = fy/Es (21.2.2.1) | F15: =F9/F10 -> 0.0020689655
A16: As provided (in²/ft) (from bar selection) | F16: 0.79 | H16: if we use Bar #8
A17: a = As*fy / (0.85 f'c b) (in) (22.2.2.4.1) | F17: =F16*F9/(0.85*F8*F7) -> 1.1617647 | H17: Check per member type
A18: c = a/β1 (in) (22.2.2.4.1) | F18: =IF(F17="","",F17/F14) -> 1.366782
A19: Net tensile strain, εt = 0.003*(d-c)/c (22.2.2.1) | F19: =0.003*(F6-F18)/F18 -> 0.021144304
A20: =IF(F19="","",IF(F19>=F15+0.003,0.9,IF(F19<=F15,0.65,0.65+0.25*(F19-F15)/0.003))) -> 0.9
A21: Mn = As*fy*(d-a/2) (lb-in/ft) | F21: =IF(F16="","",F16*F9*(F6 - F17/2)) -> 493866.18
A22: ϕMn (kip-in/ft) | F22: =IF(F21="","",A20*F21/1000) -> 444.47956 | H22: Options: No.4, No.5, No.6
A23: Utilization = Mu / (ϕMn) | F23: =IF(OR(F5="",F22=""),"",F5/F22) -> 0.026997867
A24: Required spacing s (in) for As provided | F24: =IF(F18="","",(F23*12)/F18) -> 0.23703444 | H24: Spacing = Ab*12/As
A25: Reference: As required assuming ϕ = 0.90 (tension-controlled)
A26: Mn_req = Mu/ϕ (lb-in/ft) | F26: =IF(F5="","",(F5*1000)/0.9) -> 13333.333
A27: As_req (in²/ft) (steel yields) | F27: =IF(F5="","",(F9*F6 - SQRT((F9*F6)^2 - 4*(F9^2/(2*0.85*F8*F7))*F26))/(2*(F9^2/(2*0.85*F8*F7)))) -> 0.020229375
A29: Bar Selection Helper
A31: Select bar size | F31: No.6
A32: Bar area Ab (in²) | F32: =IF(F31="No.4",0.2,IF(F31="No.5",0.31,IF(F31="No.6",0.44,IF(F31="No.7",0.6,IF(F31="No.8",0.79,""))))) -> 0.44
A33: Provide spacing s (in) | F33: 5 | G33: Assumption
A34: As provided = Ab*(12/s) (in²/ft) | F34: =IF(OR(F32="",F33=""),"",F32*12/F33) -> 1.056
A35: Spacing for As_req (in) = Ab*12/As_req | F35: =IF(OR(F32="",F27=""),"",F32*12/F27) -> 261.00658

Sheet Shear Checks (legacy)
A1: One-Way & Two-Way (Punching) Shear Checks (Generic)
A3: Inputs
A5: Factored shear demand Vu (kips) | H5: Enter from analysis
A6: Effective depth d (in) | F6: ='Flexure (Ring Footing)'!F6 -> 11
A7: Concrete strength f'c (psi) | F7: =Inputs!F9 -> 4000
A8: Phi for shear, ϕ | F8: =0.75 -> 0.75
A9: One-way shear width b (in) | F9: =12 -> 12 | H9: Per 1-ft strip
A10: Punching perimeter bo (in) | H10: Enter perimeter at d/2 from load area
A12: One-Way Shear (ACI 318-19)
A14: Vc = 2*sqrt(f'c)*b*d (lb) | F14: =IF(OR(F7="",F9="",F6=""),"",2*SQRT(F7)*F9*F6) -> 16696.826
A15: ϕVc (kips) | F15: =IF(F14="","",F8*F14/1000) -> 12.52262
A16: Utilization Vu/(ϕVc) | F16: =IF(OR(F5="",F15=""),"",F5/F15)
A18: Punching Shear (ACI 318-19)
A20: Vcp = 4*sqrt(f'c)*bo*d (lb) (interior column baseline) | F20: =IF(OR(F7="",F10="",F6=""),"",4*SQRT(F7)*F10*F6)
A21: ϕVcp (kips) | F21: =IF(F20="","",F8*F20/1000)
A22: Utilization Vu/(ϕVcp) | F22: =IF(OR(F5="",F21=""),"",F5/F21)

Sheet Shear & Bearing (ACI 21-22)
A1: Shear & Bearing Checks (ACI 318-19 Ch. 21–22)
A3: Inputs
A4: Concrete strength, f'c (psi) | C4: =Inputs!F9 -> 4000 | D4: psi
A5: Lightweight factor, λ (Table 19.2.4.1) | C5: =Inputs!F15 -> 1
A6: Shear strength reduction factor, ϕv (Table 21.2.1) | C6: 0.75
A7: Bearing strength reduction factor, ϕb (Table 21.2.1) | C7: 0.65
A8: Effective depth, d (in) | C8: ='Flexure (Ring Footing)'!F6 -> 11 | D8: in
A9: Strip width, b_w (in) (use 12 in for per-foot strip) | C9: 12 | D9: in
A10: As provided for strip (in²/ft) (from flexure sheet) | C10: ='Flexure (Ring Footing)'!F16 -> 0.79 | D10: in²/ft | G10: x
A11: Member overall thickness, h (in) | C11: =Geometry!F7*12 -> 14 | D11: in
A13: Derived terms
A14: Size effect factor, λs = min(1, 2/(1 + d/10)) (Eq. 22.5.5.1.3) | C14: =MIN(1,2/(1 + C8/10)) -> 0.95238095
A15: Reinforcement ratio, ρw = As/(b_w*d) | C15: =C10/(C9*C8) -> 0.0059848485
A16: Gross area for strip, Ag = bw*h | C16: =C9*C11 -> 168 | D16: in²
A19: One-Way Shear (22.5) — No shear reinforcement (use Table 22.5.5.1(c))
A20: Factored one-way shear demand, Vu (kips/ft) | D20: kips/ft
A21: Axial load Nu on strip (kips) (compression +, tension −) (Table 22.5.5.1 note) | C21: 0 | D21: kips
A22: Vc (lb/ft) = [8·λs·λ·ρw^(1/3)·√f'c + Nu/(6Ag)] · b_w · d (Table 22.5.5.1(c)) | C22: =IF(OR($C$13="",$C$12="",$C$4="",$C$5="",$C$8="",$C$9="",$C$14=""),"",MAX(0,(8*$C$12*$C$5*POWER($C$13,1/3)*SQRT($C$4)+($C$21*1000)/(6*$C$14))*$C$9*$C$8)) | D22: lb/ft
A23: ϕ·Vc (kips/ft) | C23: =IF(C22="","",$C$6*C22/1000) | D23: kips/ft
A24: Utilization = Vu / (ϕ·Vc) | C24: =IF(OR(C20="",C23=""),"",C20/C23)
A26: Two-Way (Punching) Shear (22.6) — No shear reinforcement (Table 22.6.5.2)
A27: Factored punching shear demand, Vu,p (kips) | D27: kips
A28: Critical perimeter, b0 (in) at d/2 from loaded area (22.6.4.1) | D28: in
A29: β = long/short side ratio of loaded area (Table 22.6.5.2 note) | C29: 1
A30: Column / load location (Interior / Edge / Corner) (22.6.5.3) | C30: Interior
A31: αs (22.6.5.3) = 40 interior, 30 edge, 20 corner | C31: =IF(C30="Interior",40,IF(C30="Edge",30,IF(C30="Corner",20,""))) -> 40
A32: vc(a) = 4·λs·λ·√f'c (Table 22.6.5.2(a)) | C32: =IF(OR($C$12="",$C$5="",$C$4=""),"",4*$C$12*$C$5*SQRT($C$4)) | D32: psi
A33: vc(b) = (2 + 4/β)·λs·λ·√f'c (Table 22.6.5.2(b)) | C33: =IF(OR(C29="",$C$12="",$C$5="",$C$4=""),"",(2 + 4/C29)*$C$12*$C$5*SQRT($C$4)) | D33: psi
A34: vc(c) = (2 + αs·d/b0)·λs·λ·√f'c (Table 22.6.5.2(c)) | C34: =IF(OR(C28="",C31="",$C$12="",$C$5="",$C$4=""),"",(2 + C31*$C$8/C28)*$C$12*$C$5*SQRT($C$4)) | D34: psi
A35: vc = least of (a),(b),(c) (Table 22.6.5.2) | C35: =IF(OR(C32="",C33="",C34=""),"",MIN(C32,C33,C34)) | D35: psi
A36: Vc,p (lb) = vc·b0·d | C36: =IF(OR(C35="",C28=""),"",C35*C28*$C$8) | D36: lb
A37: ϕ·Vc,p (kips) | C37: =IF(C36="","",$C$6*C36/1000) | D37: kips
A38: Utilization = Vu,p / (ϕ·Vc,p) | C38: =IF(OR(C27="",C37=""),"",C27/C37)
A40: Bearing (22.8) — Concrete bearing strength
A41: Factored compressive force through bearing, Bu (kips) | D41: kips
A42: Loaded area, A1 (in²) | D42: in²
A43: Supporting area, A2 (in²) (lower base of 1V:2H frustum) (22.8.3.2) | D43: in²
A44: Supporting surface wider on all sides than loaded area? (Yes/No) | C44: Yes
A45: Bn (lb) per Table 22.8.3.2 | C45: =IF(OR($C$4="",C42=""),"",IF(C44="Yes",IF(C43="","",MIN(0.85*$C$4*C42*SQRT(C43/C42),2*(0.85*$C$4*C42))),0.85*$C$4*C42)) | D45: lb
A46: ϕ·Bn (kips) | C46: =IF(C45="","",$C$7*C45/1000) | D46: kips
...

Sheet Summary
A1: Design Summary
A3: Geometry (as-designed defaults)
A5: Ringwall thickness (ft) | F5: =Geometry!F3 -> 1.6666667
A6: Footing width B (ft) | F6: =Geometry!F4 -> 3.0833333
A7: Foundation centerline radius R_cl (ft) | F7: =Geometry!F5 -> 9
A8: Plan area A (ft^2) | F8: =Geometry!F14 -> 174.35839
A9: Service bearing q_s (ksf) | F9: ='Bearing & Stability'!F14 -> 0.96005814
A10: Bearing utilization | F10: ='Bearing & Stability'!F15 -> 0.24001454
A11: Flexure As provided (in²/ft) | F11: ='Flexure (Ring Footing)'!F16 -> 0.79
A12: Flexure utilization Mu/(ϕMn) | F12: ='Flexure (Ring Footing)'!F23 -> 0.026997867
A13: Provided bar spacing s (in) | F13: ='Flexure (Ring Footing)'!F33 -> 5
A14: One-way shear utilization Vu/(ϕVc) | F14: ='Shear & Bearing (ACI 21-22)'!C24
A15: Punching shear utilization Vu,p/(ϕVc,p) | F15: ='Shear & Bearing (ACI 21-22)'!C38
A16: ACI concrete bearing utilization Bu/(ϕBn) | F16: ='Shear & Bearing (ACI 21-22)'!C47

Sheet Thank Information 
A1: Volumn (Gal.) | B1: Diameter (ft) | C1: Centroied (ft) | D1: tank height (ft) | E1: Weight of water (Kips) | F1: Weight of steel (Kips) | G1: Total weight (Kips) | H1: projected area (ft2)
A2: 50K-DE | B2: 24 | C2: 11.5 | D2: 23.001 | E2: 421 | F2: 25.0264 | G2: =F2+E2 -> 446.0264 | H2: 470
A3: 100K-DE | B3: 32 | C3: 12.6 | D3: 25.2156 | E3: 879 | F3: 40.3865 | G3: =F3+E3 -> 919.3865 | H3: 612
A4: 200K-DE | B4: 38 | C4: 16 | D4: 31.5884 | E4: 1729 | F4: 63.6953 | G4: =F4+E4 -> 1792.6953 | H4: 982
A5: 250K-TORO | B5: 43 | C5: 14.1 | D5: 29.6777 | E5: 2139 | F5: 69.913 | G5: =F5+E5 -> 2208.913 | H5: 1067
A6: 300K-TORO | B6: 43 | C6: 16 | D6: 34.5944 | E6: 2581 | F6: 84.741 | G6: =F6+E6 -> 2665.741 | H6: 1278
A7: 400K-TORO | B7: 50 | C7: 15.8 | D7: 34.3946 | E7: 3353 | F7: 83.7002 | G7: =F7+E7 -> 3436.7002 | H7: 1437
A8: 500K-TORO | B8: 56 | C8: 15 | D8: 34.8552 | E8: 4199 | F8: 133.145 | G8: =F8+E8 -> 4332.145 | H8: 1617
