Workbook

Sheet Total weight modified
A1: wind load paramets | P1: seismic base shear
A2: kzt | B2: 1 | P2: Ss | Q2: 0.068 | R2: g
A3: kd | B3: 1 | P3: S1 | Q3: 0.031 | R3: g
A4: I | B4: 1.15 | P4: SDS | Q4: =2/3*1.6*Q2 -> 0.072533333 | R4: g
A5: V | B5: 90 | C5: mph | P5: SD1 | Q5: =2/3*2.4*Q3 -> 0.0496 | R5: g
A6: exposure | B6: C | P6: Ri | Q6: 3
A7: a | B7: =IF(B6="C",9.5,11.5) -> 9.5 | P7: Is | Q7: 1.5
A8: Zg | B8: =IF(B6="C",900,700) -> 900 | C8: ft | P8: TL | Q8: 12 | R8: sec
A9: G | B9: 1 | P9: Ti | Q9: 4 | R9: sec
A10: Cf | B10: 0.5 | P10: Ts | Q10: =Q5/Q4 -> 0.68382353 | R10: sec
A11: l | B11: 0.6 | P11: Sai | Q11: =IF(Q9<Q10,Q4,IF(Q9>Q8,Q5*Q8/Q9^2,Q5/Q9)) -> 0.0124
A12: l(0.00256 Kzt Kd I V2) | B12: =B11*0.00256*B2*B3*B4*B5^2 -> 14.30784 | P12: l | Q12: 0.7
A13: cylinder weight 1 | D13: cylinder weight 2 | G13: cylinder weight 3 | J13: cylinder weight 4 | P13: Ai | Q13: =MAX(Q12*Q11*Q7/Q6,0.36*Q3*Q7/Q6) -> 0.00558 | R13: ft/s2
A14: Sequence number | B14: 6 | D14: Sequence number | E14: 7 | G14: Sequence number | H14: 8 | J14: Sequence number | K14: 9 | P14: COM | Q14: =(B29+E29+H29+K29+H54+E54+B54+B68*B72+K54+N54)/(B82+B81) -> 140.78934
A15: Thickness | B15: =5/8 -> 0.625 | C15: in | D15: Thickness | E15: =9/16 -> 0.5625 | F15: in | G15: Thickness | H15: 0.5 | I15: in | J15: Thickness | K15: =7/16 -> 0.4375 | L15: in | P15: V | Q15: =Q13*(B81+B82) -> 8.7179127 | R15: kips
A16: hi | B16: 25 | C16: ft | D16: hi | E16: =B18 -> 33.833333 | G16: hi | H16: =E18 -> 65.833333 | I16: ft | J16: hi | K16: =H18 -> 113.83333 | L16: ft | P16: Seismic base moment | Q16: =Q15*Q14 -> 1227.3892 | R16: kips-ft
A17: Height of the cylinder | B17: =8+10/12 -> 8.8333333 | C17: ft | D17: Height of the cylinder | E17: 32 | F17: ft | G17: Height of the cylinder | H17: 48 | I17: ft | J17: Height of the cylinder | K17: 24 | L17: ft
A18: hf | B18: =B16+B17 -> 33.833333 | C18: ft | D18: hf | E18: =E16+E17 -> 65.833333 | G18: hf | H18: =H16+H17 -> 113.83333 | I18: ft | J18: hf | K18: =K16+K17 -> 137.83333 | L18: ft
A19: Diameter of the cylinder | B19: 8 | C19: ft | D19: Diameter of the cylinder | E19: 8 | F19: ft | G19: Diameter of the cylinder | H19: 8 | I19: ft | J19: Diameter of the cylinder | K19: 8 | L19: ft
A20: Awind | B20: =IF(B15=0,0,B19*B17) -> 70.666667 | C20: ft2 | D20: Awind | E20: =IF(E15=0,0,E19*E17) -> 256 | F20: ft2 | G20: Awind | H20: =IF(H15=0,0,H19*H17) -> 384 | I20: ft2 | J20: Awind | K20: =IF(K15=0,0,K19*K17) -> 192 | L20: ft2
A21: Centroid | B21: =B16+B17/2 -> 29.416667 | C21: ft | D21: Centroid | E21: =E16+E17/2 -> 49.833333 | F21: ft | G21: Centroid | H21: =H16+H17/2 -> 89.833333 | I21: ft | J21: Centroid | K21: =K16+K17/2 -> 125.83333 | L21: ft
A22: kzi | B22: =2.01*(MAX(B16,15)/$B$8)^(2/$B$7) -> 0.94526467 | D22: kzi | E22: =2.01*(MAX(E16,15)/$B$8)^(2/$B$7) -> 1.0074363 | G22: kzi | H22: =2.01*(MAX(H16,15)/$B$8)^(2/$B$7) -> 1.1589934 | J22: kzi | K22: =2.01*(MAX(K16,15)/$B$8)^(2/$B$7) -> 1.300616
A23: kzf | B23: =2.01*(MAX(B18,15)/$B$8)^(2/$B$7) -> 1.0074363 | D23: kzf | E23: =2.01*(MAX(E18,15)/$B$8)^(2/$B$7) -> 1.1589934 | G23: kzf | H23: =2.01*(MAX(H18,15)/$B$8)^(2/$B$7) -> 1.300616 | J23: kzf | K23: =2.01*(MAX(K18,15)/$B$8)^(2/$B$7) -> 1.3540685
A24: qzi | B24: =MAX(B22*$B$12,30*$B$10) -> 15 | C24: psf | D24: qzi | E24: =MAX(E22*$B$12,30*$B$10) -> 15 | F24: psf | G24: qzi | H24: =MAX(H22*$B$12,30*$B$10) -> 16.582692 | I24: psf | J24: qzi | K24: =MAX(K22*$B$12,30*$B$10) -> 18.609006 | L24: psf
A25: qzf | B25: =MAX(B23*$B$12,30*$B$10) -> 15 | C25: psf | D25: qzf | E25: =MAX(E23*$B$12,30*$B$10) -> 16.582692 | F25: psf | G25: qzf | H25: =MAX(H23*$B$12,30*$B$10) -> 18.609006 | I25: psf | J25: qzf | K25: =MAX(K23*$B$12,30*$B$10) -> 19.373796 | L25: psf
A26: F | B26: =(B24+B25)/2*B20/1000 -> 1.06 | C26: kips | D26: F | E26: =(E24+E25)/2*E20/1000 -> 4.0425846 | F26: kips | G26: F | H26: =(H24+H25)/2*H20/1000 -> 6.7568061 | I26: kips | J26: F | K26: =(K24+K25)/2*K20/1000 -> 3.6463489 | L26: kips | P26: Wind base shear | Q26: =K26+H26+E26+B26 -> 15.50574 | R26: kips
A27: F location | B27: =B16+((B24*B17^2/2+2/3*0.5*B17^2*(B25-B24))/(B24*B17+0.5*B17*(B25-B24))) -> 29.416667 | C27: ft | D27: F location | E27: =E16+((E24*E17^2/2+2/3*0.5*E17^2*(E25-E24))/(E24*E17+0.5*E17*(E25-E24))) -> 50.100601 | F27: ft | G27: F location | H27: =H16+((H24*H17^2/2+2/3*0.5*H17^2*(H25-H24))/(H24*H17+0.5*H17*(H25-H24))) -> 90.293968 | I27: ft | J27: F location | K27: =K16+((K24*K17^2/2+2/3*0.5*K17^2*(K25-K24))/(K24*K17+0.5*K17*(K25-K24))) -> 125.91387 | L27: ft
A28: Wind moment At base | B28: =B27*B26 -> 31.181667 | C28: kips | D28: Wind moment At base | E28: =E27*E26 -> 202.53592 | F28: kips | G28: Wind moment At base | H28: =H27*H26 -> 610.09883 | I28: kips | J28: Wind moment At base | K28: =K27*K26 -> 459.12592 | L28: kips | P28: Wind base moment | Q28: =K28+H28+E28+B28 -> 1302.9423 | R28: kips-ft
A29: Center of mass x weight | B29: =B30*B21 -> 165.58314 | D29: Center of mass x weight | E29: =E30*E21 -> 915.15563 | G29: Center of mass x weight | H29: =H30*H21 -> 2201.0788 | J29: Center of mass x weight | K29: =K30*K21 -> 1349.7582
A30: Weight | B30: =PI()/4*(B19^2-(B19-2*B15/12)^2)*B17*490/1000 -> 5.6288885 | C30: kips | D30: Weight | E30: =PI()/4*(E19^2-(E19-2*E15/12)^2)*E17*490/1000 -> 18.364327 | F30: kips | G30: Weight | H30: =PI()/4*(H19^2-(H19-2*H15/12)^2)*H17*490/1000 -> 24.501805 | I30: kips | J30: Weight | K30: =PI()/4*(K19^2-(K19-2*K15/12)^2)*K17*490/1000 -> 10.726555 | L30: kips | P30: weight of steel | Q30: =K30+H30+E30+B30 -> 59.221575 | R30: kips
A31: frustum weight 1 | D31: frustum weight 2 | G31: frustum weight 3 | J31: frustum weight 4 | M31: frustum weight 5
A32: Sequence number | B32: 1 | D32: Sequence number | E32: 2 | G32: Sequence number | H32: 3 | J32: Sequence number | K32: 4 | M32: Sequence number | N32: 5
A33: Thickness | B33: =7/16 -> 0.4375 | C33: in | D33: Thickness | E33: =9/16 -> 0.5625 | F33: in | G33: Thickness | H33: =5/8 -> 0.625 | I33: in | J33: Thickness | K33: 0 | L33: in | M33: Thickness | N33: 0 | O33: in
A34: hi | B34: 0 | C34: ft | D34: hi | E34: =B36 -> 14 | F34: ft | G34: hi | H34: =E36 -> 21 | I34: ft | J34: hi | K34: 0 | L34: ft | M34: hi | N34: 0 | O34: ft
A35: Height of the cone | B35: 14 | C35: ft | D35: Height of the cone | E35: 7 | F35: ft | G35: Height of the cone | H35: 4 | I35: ft | J35: Height of the cone | K35: 0 | L35: ft | M35: Height of the cone | N35: 0 | O35: ft
A36: hf | B36: =B35+B34 -> 14 | C36: ft | D36: hf | E36: =E35+E34 -> 21 | F36: ft | G36: hf | H36: =H35+H34 -> 25 | I36: ft | J36: hf | K36: =K35+K34 -> 0 | L36: ft | M36: hf | N36: =N35+N34 -> 0 | O36: ft
A37: Bottom diameter | B37: 25 | C37: ft | D37: Bottom diameter | E37: =B38 -> 15.48 | F37: ft | G37: Bottom diameter | H37: =E38 -> 10.72 | I37: ft | J37: Bottom diameter | K37: 0 | L37: ft | M37: Bottom diameter | N37: =K38 -> 0 | O37: ft
A38: Top diameter | B38: =B37-(25-8)/(25)*(14) -> 15.48 | C38: ft | D38: Top diameter | E38: =E37-(25-8)/(25)*(7) -> 10.72 | F38: ft | G38: Top diameter | H38: =H37-(25-8)/(25)*(4) -> 8 | I38: ft | J38: Top diameter | K38: 0 | L38: ft | M38: Top diameter | N38: 0 | O38: ft
A39: S1 | B39: =ROUND(PI()*B38^2/4,2) -> 188.21 | C39: ft2 | D39: S1 | E39: =ROUND(PI()*E38^2/4,2) -> 90.26 | F39: ft2 | G39: S1 | H39: =ROUND(PI()*H38^2/4,2) -> 50.27 | I39: ft2 | J39: S1 | K39: =ROUND(PI()*K38^2/4,2) -> 0 | L39: ft2 | M39: S1 | N39: =ROUND(PI()*N38^2/4,2) -> 0 | O39: ft2
A40: S2 | B40: =ROUND(PI()*B37^2/4,2) -> 490.87 | C40: ft2 | D40: S2 | E40: =ROUND(PI()*E37^2/4,2) -> 188.21 | F40: ft2 | G40: S2 | H40: =ROUND(PI()*H37^2/4,2) -> 90.26 | I40: ft2 | J40: S2 | K40: =ROUND(PI()*K37^2/4,2) -> 0 | L40: ft2 | M40: S2 | N40: =ROUND(PI()*N37^2/4,2) -> 0 | O40: ft2
...

Sheet Design table
G1: Gravity Loads (per segemnet) | J1: Gravity Loads (cumulative) | M1: Wind Load (per segement)
A2: Segement | B2: Diameter(in) | C2: Thickness(in) | D2: A (in2) | E2: I (in4) | F2: S (in3) | G2: Wwater | H2: Wsnow | I2: Wself-weight | J2: Wwater | K2: Wsnow | L2: Wself-weight | M2: Fwind | N2: V wind | O2: Base Elevation(ft) | P2: load location | Q2: Arm length | R2: F x Arm | S2: Mwind
A3: Tank | B3: 0 | C3: 0 | D3: - | E3: - | F3: - | G3: ='Total weight modified'!B70 -> 1283 | H3: ='Content, Snow and miscell.'!B5+'Content, Snow and miscell.'!F2 -> 20.674502 | I3: ='Total weight modified'!B71 -> 54.9636 | J3: {=G3:I3} -> 1283 | K3: 20.674502 | L3: 54.9636 | M3: ='Total weight modified'!B67 -> 14.133121 | N3: =M3 -> 14.133121 | O3: ='Total weight modified'!B61 -> 137.83333 | P3: ='Total weight modified'!B68 -> 160.73333 | Q3: =P3-O3 -> 22.9 | R3: =M3*(Q3) -> 323.64847 | S3: =R3 -> 323.64847
A4: 9 | B4: =('Total weight modified'!K19)*12 -> 96 | C4: ='Total weight modified'!K15 -> 0.4375 | D4: =PI()/4*(B4^2-(B4-C4*2)^2) -> 131.34557 | E4: =PI()/64*(B4^4-(B4-C4*2)^4) -> 149937.25 | F4: =IF(B4=0,0,E4/B4*2) -> 3123.6928 | G4: 0 | H4: 0 | I4: ='Total weight modified'!K30 -> 10.726555 | J4: =J3+G4 -> 1283 | K4: =K3+H4 -> 20.674502 | L4: =L3+I4 -> 65.690155 | M4: ='Total weight modified'!K26 -> 3.6463489 | N4: =N3+M4 -> 17.77947 | O4: ='Total weight modified'!K16 -> 113.83333 | P4: ='Total weight modified'!K27 -> 125.91387 | Q4: =P4-O4 -> 12.080541 | R4: =M4*(Q4) -> 44.049866 | S4: =R4+M3*(P3-O4) -> 706.89323
A5: 8 | B5: =('Total weight modified'!H19)*12 -> 96 | C5: ='Total weight modified'!H15 -> 0.5 | D5: =PI()/4*(B5^2-(B5-C5*2)^2) -> 150.01105 | E5: =PI()/64*(B5^4-(B5-C5*2)^4) -> 171021.97 | F5: =IF(B5=0,0,E5/B5*2) -> 3562.9577 | G5: =G4 -> 0 | H5: =H4 -> 0 | I5: ='Total weight modified'!H30 -> 24.501805 | J5: =J4+G5 -> 1283 | K5: =K4+H5 -> 20.674502 | L5: =L4+I5 -> 90.19196 | M5: ='Total weight modified'!H26 -> 6.7568061 | N5: =N4+M5 -> 24.536276 | O5: ='Total weight modified'!H16 -> 65.833333 | P5: ='Total weight modified'!H27 -> 90.293968 | Q5: =P5-O5 -> 24.460634 | R5: =M5*(Q5) -> 165.27576 | S5: =R5+M3*(P3-O5)+M4*(P4-O5) -> 1725.5835
A6: 7 | B6: =('Total weight modified'!E19)*12 -> 96 | C6: ='Total weight modified'!E15 -> 0.5625 | D6: =PI()/4*(B6^2-(B6-C6*2)^2) -> 168.65198 | E6: =PI()/64*(B6^4-(B6-C6*2)^4) -> 192023.62 | F6: =IF(B6=0,0,E6/B6*2) -> 4000.4922 | G6: =G5 -> 0 | H6: =H5 -> 0 | I6: ='Total weight modified'!E30 -> 18.364327 | J6: =J5+G6 -> 1283 | K6: =K5+H6 -> 20.674502 | L6: =L5+I6 -> 108.55629 | M6: ='Total weight modified'!E26 -> 4.0425846 | N6: =N5+M6 -> 28.57886 | O6: ='Total weight modified'!E16 -> 33.833333 | P6: ='Total weight modified'!E27 -> 50.100601 | Q6: =P6-O6 -> 16.267267 | R6: =M6*(Q6) -> 65.761805 | S6: =R6+M3*(P3-O6)+M4*(P4-O6)+M5*(P5-O6) -> 2576.5062
A7: 6 | B7: =('Total weight modified'!B19)*12 -> 96 | C7: ='Total weight modified'!B15 -> 0.625 | D7: =PI()/4*(B7^2-(B7-C7*2)^2) -> 187.26837 | E7: =PI()/64*(B7^4-(B7-C7*2)^4) -> 212942.43 | F7: =IF(B7=0,0,E7/B7*2) -> 4436.3006 | G7: =G6 -> 0 | H7: =H6 -> 0 | I7: ='Total weight modified'!B30 -> 5.6288885 | J7: =J6+G7 -> 1283 | K7: =K6+H7 -> 20.674502 | L7: =L6+I7 -> 114.18518 | M7: ='Total weight modified'!B26 -> 1.06 | N7: =N6+M7 -> 29.63886 | O7: ='Total weight modified'!B16 -> 25 | P7: ='Total weight modified'!B27 -> 29.416667 | Q7: =P7-O7 -> 4.4166667 | R7: =M7*(Q7) -> 4.6816667 | S7: =R7+M3*(P3-O7)+M4*(P4-O7)+M5*(P5-O7)+M6*(P6-O7) -> 2833.6344
A8: 5 | B8: ='Total weight modified'!N37*12 -> 0 | C8: ='Total weight modified'!N33 -> 0 | D8: =PI()/4*(B8^2-(B8-C8*2)^2) -> 0 | E8: =PI()/64*(B8^4-(B8-C8*2)^4) -> 0 | F8: =IF(B8=0,0,E8/B8*2) -> 0 | G8: =G7 -> 0 | H8: =H7 -> 0 | I8: ='Total weight modified'!N56 -> 0 | J8: =J7+G8 -> 1283 | K8: =K7+H8 -> 20.674502 | L8: =L7+I8 -> 114.18518 | M8: ='Total weight modified'!N51 -> 0 | N8: =N7+M8 -> 29.63886 | O8: ='Total weight modified'!N34 -> 0 | P8: ='Total weight modified'!N52 -> 0 | Q8: =P8-O8 -> 0 | R8: =M8*(Q8) -> 0 | S8: =R8+M3*(P3-O8)+M4*(P4-O8)+M5*(P5-O8)+M6*(P6-O8)+M7*(P7-O8) -> 3574.606
A9: 4 | B9: ='Total weight modified'!K37*12 -> 0 | C9: ='Total weight modified'!K33 -> 0 | D9: =PI()/4*(B9^2-(B9-C9*2)^2) -> 0 | E9: =PI()/64*(B9^4-(B9-C9*2)^4) -> 0 | F9: =IF(B9=0,0,E9/B9*2) -> 0 | G9: =G8 -> 0 | H9: =H8 -> 0 | I9: ='Total weight modified'!K56 -> 0 | J9: =J8+G9 -> 1283 | K9: =K8+H9 -> 20.674502 | L9: =L8+I9 -> 114.18518 | M9: ='Total weight modified'!K51 -> 0 | N9: =N8+M9 -> 29.63886 | O9: ='Total weight modified'!K34 -> 0 | P9: ='Total weight modified'!K52 -> 0 | Q9: =P9-O9 -> 0 | R9: =M9*(Q9) -> 0 | S9: =R9+M3*(P3-O9)+M4*(P4-O9)+M5*(P5-O9)+M6*(P6-O9)+M7*(P7-O9)+M8*(P8-O9) -> 3574.606
A10: 3 | B10: =('Total weight modified'!H37)*12 -> 128.64 | C10: ='Total weight modified'!H33 -> 0.625 | D10: =PI()/4*(B10^2-(B10-C10*2)^2) -> 251.35686 | E10: =PI()/64*(B10^4-(B10-C10*2)^4) -> 514911.79 | F10: =IF(B10=0,0,E10/B10*2) -> 8005.4694 | G10: =G9 -> 0 | H10: =H9 -> 0 | I10: ='Total weight modified'!H56 -> 2.989 | J10: =J9+G10 -> 1283 | K10: =K9+H10 -> 20.674502 | L10: =L9+I10 -> 117.17418 | M10: ='Total weight modified'!H51 -> 0.5616 | N10: =N9+M10 -> 30.20046 | O10: ='Total weight modified'!H34 -> 21 | P10: ='Total weight modified'!H52 -> 23 | Q10: =P10-O10 -> 2 | R10: =M10*(Q10) -> 1.1232 | S10: =R10+M3*(P3-O10)+M4*(P4-O10)+M5*(P5-O10)+M6*(P6-O10)+M7*(P7-O10)+M8*(P8-O10)+M9*(P9-O10) -> 2953.3131
A11: 2 | B11: =('Total weight modified'!E37)*12 -> 185.76 | C11: ='Total weight modified'!E33 -> 0.5625 | D11: =PI()/4*(B11^2-(B11-C11*2)^2) -> 327.271 | E11: =PI()/64*(B11^4-(B11-C11*2)^4) -> 1403110.2 | F11: =IF(B11=0,0,E11/B11*2) -> 15106.699 | G11: =G10 -> 0 | H11: =H10 -> 0 | I11: ='Total weight modified'!E56 -> 6.6199 | J11: =J10+G11 -> 1283 | K11: =K10+H11 -> 20.674502 | L11: =L10+I11 -> 123.79408 | M11: ='Total weight modified'!E51 -> 1.3755 | N11: =N10+M11 -> 31.57596 | O11: ='Total weight modified'!E34 -> 14 | P11: ='Total weight modified'!E52 -> 17.5 | Q11: =P11-O11 -> 3.5 | R11: =M11*(Q11) -> 4.81425 | S11: =R11+M3*(P3-O11)+M4*(P4-O11)+M5*(P5-O11)+M6*(P6-O11)+M7*(P7-O11)+M8*(P8-O11)+M9*(P9-O11)+M10*(P10-O11) -> 3169.5306
A12: 1 | B12: =('Total weight modified'!B37)*12 -> 300 | C12: ='Total weight modified'!B33 -> 0.4375 | D12: =PI()/4*(B12^2-(B12-C12*2)^2) -> 411.73272 | E12: =PI()/64*(B12^4-(B12-C12*2)^4) -> 4618502.8 | F12: =IF(B12=0,0,E12/B12*2) -> 30790.018 | G12: =G11 -> 0 | H12: =H11 -> 0 | I12: ='Total weight modified'!B56 -> 15.8809 | J12: =J11+G12 -> 1283 | K12: =K11+H12 -> 20.674502 | L12: =L11+I12 -> 139.67498 | M12: ='Total weight modified'!B51 -> 4.2504 | N12: =N11+M12 -> 35.82636 | O12: ='Total weight modified'!B34 -> 0 | P12: ='Total weight modified'!B52 -> 7 | Q12: =P12-O12 -> 7 | R12: =M12*(Q12) -> 29.7528 | S12: =R12+M3*(P3-O12)+M4*(P4-O12)+M5*(P5-O12)+M6*(P6-O12)+M7*(P7-O12)+M8*(P8-O12)+M9*(P9-O12)+M10*(P10-O12)+M11*(P11-O12) -> 3641.3468
A14: Allowable compressive stress for column
A15: FY | B15: 36000 | C15: psi
A16: k | B16: 2.1
A17: L | B17: =177*12 -> 2124 | C17: in
A18: (R/t)c | B18: =VLOOKUP(B15,P21:Q27,2,FALSE) -> 334
A19: E | B19: 29000000 | C19: psi
A20: Segement | B20: Radius(in) | C20: Thickness(in) | D20: R/t | E20: A (in2) | F20: I (in4) | G20: r(in) | H20: C0 | I20: Fl | J20: KL/r | K20: C'c | L20: kf | M20: Fa | N20: Fb | P20: Fy | Q20: (R/t)c | V20: `
A21: {=A3:A12} -> Tank | B21: - | C21: - | D21: - | E21: - | F21: - | G21: - | H21: - | I21: - | J21: - | K21: - | L21: - | M21: - | N21: {=I21:I30} -> - | P21: 30000 | Q21: 403
A22: 9 | B22: {=B4:B12/2} -> 48 | C22: {=C4:C12} -> 0.4375 | D22: =IF(B22=0,0,B22/C22) -> 109.71429 | E22: {=D4:D12} -> 131.34557 | F22: {=E4:E12} -> 149937.25 | G22: =IF(B22=0,0,SQRT(F22/E22)) -> 33.7868 | H22: =IF(B22=0,0,MAX(0.125,1022/(195+D22))) -> 3.3539616 | I22: =IF(B22=0,0,IF(D22<$B$18,MIN(233*$B$15/2/(166+D22),$B$15/2),H22*$B$19/2/D22)/1000) -> 15.211399 | J22: =IF(B22=0,0,$B$16*$B$17/G22) -> 132.01605 | K22: =IF(B22=0,0,SQRT(PI()^2*$B$19/I22/1000)) -> 137.17163 | L22: =IF(B22=0,0,IF(J22>K22,0.5*(K22/J22)^2,IF(J22<25,1,1-0.5*(J22/K22)^2))) -> 0.53687853 | M22: =IF(B22=0,0,L22*I22) -> 8.1666736 | N22: 15.211399 | P22: 32000 | Q22: 377
A23: 8 | B23: 48 | C23: 0.5 | D23: =IF(B23=0,0,B23/C23) -> 96 | E23: 150.01105 | F23: 171021.97 | G23: =IF(B23=0,0,SQRT(F23/E23)) -> 33.764812 | H23: =IF(B23=0,0,MAX(0.125,1022/(195+D23))) -> 3.5120275 | I23: =IF(B23=0,0,IF(D23<$B$18,MIN(233*$B$15/2/(166+D23),$B$15/2),H23*$B$19/2/D23)/1000) -> 16.007634 | J23: =IF(B23=0,0,$B$16*$B$17/G23) -> 132.10203 | K23: =IF(B23=0,0,SQRT(PI()^2*$B$19/I23/1000)) -> 133.71659 | L23: =IF(B23=0,0,IF(J23>K23,0.5*(K23/J23)^2,IF(J23<25,1,1-0.5*(J23/K23)^2))) -> 0.51200165 | M23: =IF(B23=0,0,L23*I23) -> 8.1959349 | N23: 16.007634 | P23: 34000 | Q23: 354
A24: 7 | B24: 48 | C24: 0.5625 | D24: =IF(B24=0,0,B24/C24) -> 85.333333 | E24: 168.65198 | F24: 192023.62 | G24: =IF(B24=0,0,SQRT(F24/E24)) -> 33.742838 | H24: =IF(B24=0,0,MAX(0.125,1022/(195+D24))) -> 3.6456599 | I24: =IF(B24=0,0,IF(D24<$B$18,MIN(233*$B$15/2/(166+D24),$B$15/2),H24*$B$19/2/D24)/1000) -> 16.687003 | J24: =IF(B24=0,0,$B$16*$B$17/G24) -> 132.18805 | K24: =IF(B24=0,0,SQRT(PI()^2*$B$19/I24/1000)) -> 130.96634 | L24: =IF(B24=0,0,IF(J24>K24,0.5*(K24/J24)^2,IF(J24<25,1,1-0.5*(J24/K24)^2))) -> 0.49080051 | M24: =IF(B24=0,0,L24*I24) -> 8.1899894 | N24: 16.687003 | P24: 36000 | Q24: 334
A25: 6 | B25: 48 | C25: 0.625 | D25: =IF(B25=0,0,B25/C25) -> 76.8 | E25: 187.26837 | F25: 212942.43 | G25: =IF(B25=0,0,SQRT(F25/E25)) -> 33.720879 | H25: =IF(B25=0,0,MAX(0.125,1022/(195+D25))) -> 3.7601177 | I25: =IF(B25=0,0,IF(D25<$B$18,MIN(233*$B$15/2/(166+D25),$B$15/2),H25*$B$19/2/D25)/1000) -> 17.273476 | J25: =IF(B25=0,0,$B$16*$B$17/G25) -> 132.27413 | K25: =IF(B25=0,0,SQRT(PI()^2*$B$19/I25/1000)) -> 128.72384 | L25: =IF(B25=0,0,IF(J25>K25,0.5*(K25/J25)^2,IF(J25<25,1,1-0.5*(J25/K25)^2))) -> 0.47351981 | M25: =IF(B25=0,0,L25*I25) -> 8.1793332 | N25: 17.273476 | P25: 38000 | Q25: 316
A26: 5 | B26: 0 | C26: 0 | D26: =IF(B26=0,0,B26/C26) -> 0 | E26: 0 | F26: 0 | G26: =IF(B26=0,0,SQRT(F26/E26)) -> 0 | H26: =IF(B26=0,0,MAX(0.125,1022/(195+D26))) -> 0 | I26: =IF(B26=0,0,IF(D26<$B$18,MIN(233*$B$15/2/(166+D26),$B$15/2),H26*$B$19/2/D26)/1000) -> 0 | J26: =IF(B26=0,0,$B$16*$B$17/G26) -> 0 | K26: =IF(B26=0,0,SQRT(PI()^2*$B$19/I26/1000)) -> 0 | L26: =IF(B26=0,0,IF(J26>K26,0.5*(K26/J26)^2,IF(J26<25,1,1-0.5*(J26/K26)^2))) -> 0 | M26: =IF(B26=0,0,L26*I26) -> 0 | N26: 0 | P26: 40000 | Q26: 299
A27: 4 | B27: 0 | C27: 0 | D27: =IF(B27=0,0,B27/C27) -> 0 | E27: 0 | F27: 0 | G27: =IF(B27=0,0,SQRT(F27/E27)) -> 0 | H27: =IF(B27=0,0,MAX(0.125,1022/(195+D27))) -> 0 | I27: =IF(B27=0,0,IF(D27<$B$18,MIN(233*$B$15/2/(166+D27),$B$15/2),H27*$B$19/2/D27)/1000) -> 0 | J27: =IF(B27=0,0,$B$16*$B$17/G27) -> 0 | K27: =IF(B27=0,0,SQRT(PI()^2*$B$19/I27/1000)) -> 0 | L27: =IF(B27=0,0,IF(J27>K27,0.5*(K27/J27)^2,IF(J27<25,1,1-0.5*(J27/K27)^2))) -> 0 | M27: =IF(B27=0,0,L27*I27) -> 0 | N27: 0
A28: 3 | B28: 64.32 | C28: 0.625 | D28: =IF(B28=0,0,B28/C28) -> 102.912 | E28: 251.35686 | F28: 514911.79 | G28: =IF(B28=0,0,SQRT(F28/E28)) -> 45.260677 | H28: =IF(B28=0,0,MAX(0.125,1022/(195+D28))) -> 3.4305432 | I28: =IF(B28=0,0,IF(D28<$B$18,MIN(233*$B$15/2/(166+D28),$B$15/2),H28*$B$19/2/D28)/1000) -> 15.59618 | J28: =IF(B28=0,0,$B$16*$B$17/G28) -> 98.549123 | K28: =IF(B28=0,0,SQRT(PI()^2*$B$19/I28/1000)) -> 135.46895 | L28: =IF(B28=0,0,IF(J28>K28,0.5*(K28/J28)^2,IF(J28<25,1,1-0.5*(J28/K28)^2))) -> 0.73539623 | M28: =IF(B28=0,0,L28*I28) -> 11.469372 | N28: 15.59618
A29: 2 | B29: 92.88 | C29: 0.5625 | D29: =IF(B29=0,0,B29/C29) -> 165.12 | E29: 327.271 | F29: 1403110.2 | G29: =IF(B29=0,0,SQRT(F29/E29)) -> 65.477506 | H29: =IF(B29=0,0,MAX(0.125,1022/(195+D29))) -> 2.8379429 | I29: =IF(B29=0,0,IF(D29<$B$18,MIN(233*$B$15/2/(166+D29),$B$15/2),H29*$B$19/2/D29)/1000) -> 12.666103 | J29: =IF(B29=0,0,$B$16*$B$17/G29) -> 68.121104 | K29: =IF(B29=0,0,SQRT(PI()^2*$B$19/I29/1000)) -> 150.32367 | L29: =IF(B29=0,0,IF(J29>K29,0.5*(K29/J29)^2,IF(J29<25,1,1-0.5*(J29/K29)^2))) -> 0.89732171 | M29: =IF(B29=0,0,L29*I29) -> 11.365569 | N29: 12.666103
A30: 1 | B30: 150 | C30: 0.4375 | D30: =IF(B30=0,0,B30/C30) -> 342.85714 | E30: 411.73272 | F30: 4618502.8 | G30: =IF(B30=0,0,SQRT(F30/E30)) -> 105.91145 | H30: =IF(B30=0,0,MAX(0.125,1022/(195+D30))) -> 1.9001328 | I30: =IF(B30=0,0,IF(D30<$B$18,MIN(233*$B$15/2/(166+D30),$B$15/2),H30*$B$19/2/D30)/1000) -> 80.359783 | J30: =IF(B30=0,0,$B$16*$B$17/G30) -> 42.114427 | K30: =IF(B30=0,0,SQRT(PI()^2*$B$19/I30/1000)) -> 59.680093 | L30: =IF(B30=0,0,IF(J30>K30,0.5*(K30/J30)^2,IF(J30<25,1,1-0.5*(J30/K30)^2))) -> 0.75101522 | M30: =IF(B30=0,0,L30*I30) -> 60.35142 | N30: 80.359783
A32: {=A20:A30} -> Segement | B32: fa | C32: fb | D32: check
A33: Tank | B33: - | C33: - | D33: -
A34: 9 | B34: =IF(D4=0,0,(J4+K4+L4)/D4) -> 10.425663 | C34: =IF(F4=0,0,S4*12/F4) -> 2.715606 | D34: =IF(B34+C34=0,"NA",B34/M22+C34/N22) -> 1.4551351
A35: 8 | B35: =IF(D5=0,0,(J5+K5+L5)/D5) -> 9.2917586 | C35: =IF(F5=0,0,S5*12/F5) -> 5.8117452 | D35: =IF(B35+C35=0,"NA",B35/M23+C35/N23) -> 1.4967642
A36: 7 | B36: =IF(D6=0,0,(J6+K6+L6)/D6) -> 8.3736388 | C36: =IF(F6=0,0,S6*12/F6) -> 7.7285676 | D36: =IF(B36+C36=0,"NA",B36/M24+C36/N24) -> 1.4855726
A37: 6 | B37: =IF(D7=0,0,(J7+K7+L7)/D7) -> 7.5712713 | C37: =IF(F7=0,0,S7*12/F7) -> 7.6648578 | D37: =IF(B37+C37=0,"NA",B37/M25+C37/N25) -> 1.3693944
A38: 5 | B38: =IF(D8=0,0,(J8+K8+L8)/D8) -> 0 | C38: =IF(F8=0,0,S8*12/F8) -> 0 | D38: =IF(B38+C38=0,"NA",B38/M26+C38/N26) -> NA
A39: 4 | B39: =IF(D9=0,0,(J9+K9+L9)/D9) -> 0 | C39: =IF(F9=0,0,S9*12/F9) -> 0 | D39: =IF(B39+C39=0,"NA",B39/M27+C39/N27) -> NA
A40: 3 | B40: =IF(D10=0,0,(J10+K10+L10)/D10) -> 5.6527148 | C40: =IF(F10=0,0,S10*12/F10) -> 4.4269431 | D40: =IF(B40+C40=0,"NA",B40/M28+C40/N28) -> 0.77670094
A41: 2 | B41: =IF(D11=0,0,(J11+K11+L11)/D11) -> 4.3617326 | C41: =IF(F11=0,0,S11*12/F11) -> 2.5177153 | D41: =IF(B41+C41=0,"NA",B41/M29+C41/N29) -> 0.58254304
A42: 1 | B42: =IF(D12=0,0,(J12+K12+L12)/D12) -> 3.5055497 | C42: =IF(F12=0,0,S12*12/F12) -> 1.4191665 | D42: =IF(B42+C42=0,"NA",B42/M30+C42/N30) -> 0.075745778

Sheet Content, Snow and  miscell.
A1: Snow Load | E1: miscellaneous load
A2: diameter to consider | B2: 17 | C2: ft | E2: miscellaneous load | F2: 15 | G2: kips
A3: area | B3: =B2^2*PI()/4 -> 226.98007 | C3: ft2
A4: Roof snow load | B4: 25 | C4: psf
A5: Snow load | B5: =B4*B3/1000 -> 5.6745017 | C5: kips

Sheet Tanks information
A1: Volumn (Gal.) | B1: Centroied (ft) | C1: tank height (ft) | D1: Weight of water (Kips) | E1: Weight of steel (Kips) | F1: Total weight (Kips) | G1: projected area (ft2)
A2: 150000 | B2: 22.9 | C2: 38.885 | D2: 1283 | E2: 54.9636 | F2: =E2+D2 -> 1337.9636 | G2: 710.41809
A3: 250000 | B3: 23.4 | C3: 43.94 | D3: 2122 | E3: 77.4918 | F3: =E3+D3 -> 2199.4918 | G3: 1292
A4: 500000 | B4: 25.27 | C4: 54.26 | D4: 4305 | E4: 142.8001 | F4: =E4+D4 -> 4447.8001 | G4: 1530
A5: 750000 | B5: 29.4 | C5: 62.15 | D5: 6257 | E5: 234.29 | F5: =E5+D5 -> 6491.29 | G5: 2016
A6: 1000000 | B6: "missing" | C6: 0 | D6: =D4*2 -> 8610 | E6: =E4*2 -> 285.6002 | F6: =E6+D6 -> 8895.6002 | G6: 0
